Workbook
Name PIZZERICHIESTE: 'MENU PIZZE'!$A$4:$A$110
Name IngredientiInFoglioPizze: 'MENU PIZZE'!$E$4:$L$110
Name Pizze: 'MENU PIZZE'!$A$4:$Q$110
Name CercaIngrediente: 'MENU PIZZE'!$S$2
Name QTAGIADISPONIBILE: INGREDIENTI!$D$3:$D$141
Name Ingredienti: INGREDIENTI!$A$3:$I$141
Name OrdineDiProduzione: 'MENU PIZZE'!$N$4:$N$110

Sheet MENU PIZZE
S1: Cerca ingrediente | U1: Aggiungi pizza | W1: Aggiungi evento | Y1: Totalizza eventi | AA1: Crea MENU
A3: Da fare | B3: DISPONIBILI (ingredienti in casa) | C3: TIPO | D3: NOME | E3: INGREDIENTI Pomodoro | F3: Mozzarella | G3: Principale 1 | H3: Principale 2 | I3: Altro 1 | J3: Altro 2 | K3: Altro 3 | L3: Altro 4 | M3: RI/DI | N3: ORDINE DI PRODUZIONE | O3: Prec | P3: Descrizione per menù | Q3: NEW
A4: 1 | B4: =MIN(SUMIF(INGREDIENTI!$B$2:$B$114,E4,INGREDIENTI!$D$2:$D$114),SUMIF(INGREDIENTI!$B$2:$B$114,F4,INGREDIENTI!$D$2:$D$114),SUMIF(INGREDIENTI!$B$2:$B$114,G4,INGREDIENTI!$D$2:$D$114),SUMIF(INGREDIENTI!$B$2:$B$114,H4,INGREDIENTI!$D$2:$D$114),SUMIF(INGREDIENTI!$B$2:$B$114,I4,INGREDIENTI!$D$2:$D$114),SUMIF(INGREDIENTI!$B$2:$B$114,J4,INGREDIENTI!$D$2:$D$114),SUMIF(INGREDIENTI!$B$2:$B$114,K4,INGREDIENTI!$D$2:$D$114),SUMIF(INGREDIENTI!$B$2:$B$114,L4,INGREDIENTI!$D$2:$D$114)) -> 0 | C4: Base | D4: MARGHERITA | E4: Pomodoro | F4: Fiordilatte | G4: Parmigiano | H4: Basilico * | I4: - | J4: - | K4: - | L4: - | M4: =IF(A4> 0,"SI",IF(B4> 0,"SI","")) -> SI | N4: 1 | O4: =SUMIF( 'TOTALI PIZZE'!A:A,D4,'TOTALI PIZZE'!B:B) -> 6 | P4: La classica Margherita con una spolverata di parmigiano | Q4: =if(SUMIF( 'TOTALI PIZZE'!A:A,D4,'TOTALI PIZZE'!B:B)=0,"NEW","")
A5: 1 | B5: =MIN(SUMIF(INGREDIENTI!$B$2:$B$114,E5,INGREDIENTI!$D$2:$D$114),SUMIF(INGREDIENTI!$B$2:$B$114,F5,INGREDIENTI!$D$2:$D$114),SUMIF(INGREDIENTI!$B$2:$B$114,G5,INGREDIENTI!$D$2:$D$114),SUMIF(INGREDIENTI!$B$2:$B$114,H5,INGREDIENTI!$D$2:$D$114),SUMIF(INGREDIENTI!$B$2:$B$114,I5,INGREDIENTI!$D$2:$D$114),SUMIF(INGREDIENTI!$B$2:$B$114,J5,INGREDIENTI!$D$2:$D$114),SUMIF(INGREDIENTI!$B$2:$B$114,K5,INGREDIENTI!$D$2:$D$114),SUMIF(INGREDIENTI!$B$2:$B$114,L5,INGREDIENTI!$D$2:$D$114)) -> 0 | C5: Speciale | D5: GAMBERI&GUACA | E5: - | F5: - | G5: Guacamole * | H5: Gamberi rossi * | I5: Stracciatella * | J5: Scorza di limone * | K5: Pepe * | L5: - | M5: =IF(A5> 0,"SI",IF(B5> 0,"SI","")) -> SI | N5: 2 | O5: =SUMIF( 'TOTALI PIZZE'!A:A,D5,'TOTALI PIZZE'!B:B) -> 0 | P5: Focaccia con in uscita: Guacamole, Gamberi rossi, Stracciatella, Scorza di limone e Pepe | Q5: =if(SUMIF( 'TOTALI PIZZE'!A:A,D5,'TOTALI PIZZE'!B:B)=0,"NEW","") -> NEW
A6: 1 | B6: =MIN(SUMIF(INGREDIENTI!$B$2:$B$114,E6,INGREDIENTI!$D$2:$D$114),SUMIF(INGREDIENTI!$B$2:$B$114,F6,INGREDIENTI!$D$2:$D$114),SUMIF(INGREDIENTI!$B$2:$B$114,G6,INGREDIENTI!$D$2:$D$114),SUMIF(INGREDIENTI!$B$2:$B$114,H6,INGREDIENTI!$D$2:$D$114),SUMIF(INGREDIENTI!$B$2:$B$114,I6,INGREDIENTI!$D$2:$D$114),SUMIF(INGREDIENTI!$B$2:$B$114,J6,INGREDIENTI!$D$2:$D$114),SUMIF(INGREDIENTI!$B$2:$B$114,K6,INGREDIENTI!$D$2:$D$114),SUMIF(INGREDIENTI!$B$2:$B$114,L6,INGREDIENTI!$D$2:$D$114)) -> 0 | C6: Speciale | D6: 4GEL&LIQUIRIZIA | E6: - | F6: Fiordilatte | G6: Pecorino | H6: Gorgonzola | I6: Parmigiano | J6: Gel di agrumi | K6: Liquirizia polvere * | L6: - | M6: =IF(A6> 0,"SI",IF(B6> 0,"SI","")) -> SI | N6: 3 | O6: =SUMIF( 'TOTALI PIZZE'!A:A,D6,'TOTALI PIZZE'!B:B) -> 4 | P6: 4 formaggi (Fiordilatte, Parmigiano, Pecorino, Gorgonzola), Gel di Agrumi, Liquirizia | Q6: =if(SUMIF( 'TOTALI PIZZE'!A:A,D6,'TOTALI PIZZE'!B:B)=0,"NEW","")
A7: 1 | B7: =MIN(SUMIF(INGREDIENTI!$B$2:$B$114,E7,INGREDIENTI!$D$2:$D$114),SUMIF(INGREDIENTI!$B$2:$B$114,F7,INGREDIENTI!$D$2:$D$114),SUMIF(INGREDIENTI!$B$2:$B$114,G7,INGREDIENTI!$D$2:$D$114),SUMIF(INGREDIENTI!$B$2:$B$114,H7,INGREDIENTI!$D$2:$D$114),SUMIF(INGREDIENTI!$B$2:$B$114,I7,INGREDIENTI!$D$2:$D$114),SUMIF(INGREDIENTI!$B$2:$B$114,J7,INGREDIENTI!$D$2:$D$114),SUMIF(INGREDIENTI!$B$2:$B$114,K7,INGREDIENTI!$D$2:$D$114),SUMIF(INGREDIENTI!$B$2:$B$114,L7,INGREDIENTI!$D$2:$D$114)) -> 0 | C7: Speciale | D7: STRACCIA CONFIT | E7: Pomodoro | F7: Fiordilatte | G7: Stracciatella * | H7: Pomodorini confit | I7: Parmigiano | J7: Basilico * | K7: Scorza di limone * | L7: - | M7: =IF(A7> 0,"SI",IF(B7> 0,"SI","")) -> SI | N7: 4 | O7: =SUMIF( 'TOTALI PIZZE'!A:A,D7,'TOTALI PIZZE'!B:B) -> 2 | P7: Fiordilatte Pomodorini Confit, Parmigiano. In uscita: Stracciatella, Basilico, scorzette di limone | Q7: =if(SUMIF( 'TOTALI PIZZE'!A:A,D7,'TOTALI PIZZE'!B:B)=0,"NEW","")
A8: 1 | B8: =MIN(SUMIF(INGREDIENTI!$B$2:$B$114,E8,INGREDIENTI!$D$2:$D$114),SUMIF(INGREDIENTI!$B$2:$B$114,F8,INGREDIENTI!$D$2:$D$114),SUMIF(INGREDIENTI!$B$2:$B$114,G8,INGREDIENTI!$D$2:$D$114),SUMIF(INGREDIENTI!$B$2:$B$114,H8,INGREDIENTI!$D$2:$D$114),SUMIF(INGREDIENTI!$B$2:$B$114,I8,INGREDIENTI!$D$2:$D$114),SUMIF(INGREDIENTI!$B$2:$B$114,J8,INGREDIENTI!$D$2:$D$114),SUMIF(INGREDIENTI!$B$2:$B$114,K8,INGREDIENTI!$D$2:$D$114),SUMIF(INGREDIENTI!$B$2:$B$114,L8,INGREDIENTI!$D$2:$D$114)) -> 0 | C8: Speciale | D8: AGLIO NERO E FUNGHI | E8: - | F8: Fiordilatte | G8: Funghi | H8: Emulsione di aglio nero * | I8: Parmigiano | J8: Prezzemolo | K8: - | L8: - | M8: =IF(A8> 0,"SI",IF(B8> 0,"SI","")) -> SI | N8: 5 | O8: =SUMIF( 'TOTALI PIZZE'!A:A,D8,'TOTALI PIZZE'!B:B) -> 0 | Q8: =if(SUMIF( 'TOTALI PIZZE'!A:A,D8,'TOTALI PIZZE'!B:B)=0,"NEW","") -> NEW
B9: =MIN(SUMIF(INGREDIENTI!$B$2:$B$114,E9,INGREDIENTI!$D$2:$D$114),SUMIF(INGREDIENTI!$B$2:$B$114,F9,INGREDIENTI!$D$2:$D$114),SUMIF(INGREDIENTI!$B$2:$B$114,G9,INGREDIENTI!$D$2:$D$114),SUMIF(INGREDIENTI!$B$2:$B$114,H9,INGREDIENTI!$D$2:$D$114),SUMIF(INGREDIENTI!$B$2:$B$114,I9,INGREDIENTI!$D$2:$D$114),SUMIF(INGREDIENTI!$B$2:$B$114,J9,INGREDIENTI!$D$2:$D$114),SUMIF(INGREDIENTI!$B$2:$B$114,K9,INGREDIENTI!$D$2:$D$114),SUMIF(INGREDIENTI!$B$2:$B$114,L9,INGREDIENTI!$D$2:$D$114)) -> 0 | C9: Speciale | D9: I TRE POMI | E9: Pomodoro giallo | F9: - | G9: Pomod.Pachino | H9: Pomodori secchi (crema) | I9: Origano * | J9: - | K9: - | L9: - | M9: =IF(A9> 0,"SI",IF(B9> 0,"SI","")) | O9: =SUMIF( 'TOTALI PIZZE'!A:A,D9,'TOTALI PIZZE'!B:B) -> 1 | P9: Base di pomodoro giallo, Pomodorini Confit, Crema di pomodori secchi, origano | Q9: =if(SUMIF( 'TOTALI PIZZE'!A:A,D9,'TOTALI PIZZE'!B:B)=0,"NEW","")
B10: =MIN(SUMIF(INGREDIENTI!$B$2:$B$114,E10,INGREDIENTI!$D$2:$D$114),SUMIF(INGREDIENTI!$B$2:$B$114,F10,INGREDIENTI!$D$2:$D$114),SUMIF(INGREDIENTI!$B$2:$B$114,G10,INGREDIENTI!$D$2:$D$114),SUMIF(INGREDIENTI!$B$2:$B$114,H10,INGREDIENTI!$D$2:$D$114),SUMIF(INGREDIENTI!$B$2:$B$114,I10,INGREDIENTI!$D$2:$D$114),SUMIF(INGREDIENTI!$B$2:$B$114,J10,INGREDIENTI!$D$2:$D$114),SUMIF(INGREDIENTI!$B$2:$B$114,K10,INGREDIENTI!$D$2:$D$114),SUMIF(INGREDIENTI!$B$2:$B$114,L10,INGREDIENTI!$D$2:$D$114)) -> 0 | C10: Speciale | D10: BACCARINA IN VASO | E10: Pomodoro | F10: - | G10: Baccalà in vasocottura | H10: Emulsione di aglio nero * | I10: Granella di mandorle * | J10: - | K10: - | L10: - | M10: =IF(A10> 0,"SI",IF(B10> 0,"SI","")) | O10: =SUMIF( 'TOTALI PIZZE'!A:A,D10,'TOTALI PIZZE'!B:B) -> 2 | P10: Rossa con Baccalà in Vasocottura, Emulsione di Aglio Nero, Granella di mandorle | Q10: =if(SUMIF( 'TOTALI PIZZE'!A:A,D10,'TOTALI PIZZE'!B:B)=0,"NEW","")
B11: =MIN(SUMIF(INGREDIENTI!$B$2:$B$114,E11,INGREDIENTI!$D$2:$D$114),SUMIF(INGREDIENTI!$B$2:$B$114,F11,INGREDIENTI!$D$2:$D$114),SUMIF(INGREDIENTI!$B$2:$B$114,G11,INGREDIENTI!$D$2:$D$114),SUMIF(INGREDIENTI!$B$2:$B$114,H11,INGREDIENTI!$D$2:$D$114),SUMIF(INGREDIENTI!$B$2:$B$114,I11,INGREDIENTI!$D$2:$D$114),SUMIF(INGREDIENTI!$B$2:$B$114,J11,INGREDIENTI!$D$2:$D$114),SUMIF(INGREDIENTI!$B$2:$B$114,K11,INGREDIENTI!$D$2:$D$114),SUMIF(INGREDIENTI!$B$2:$B$114,L11,INGREDIENTI!$D$2:$D$114)) -> 0 | C11: Speciale | D11: CECINELLA | E11: - | F11: Fiordilatte | G11: Crema di ceci * | H11: Pomod.Pachino | I11: Zucchine | J11: - | K11: - | L11: - | M11: =IF(A11> 0,"SI",IF(B11> 0,"SI","")) | O11: =SUMIF( 'TOTALI PIZZE'!A:A,D11,'TOTALI PIZZE'!B:B) -> 1 | P11: Crema di Ceci, Fiordilatte, Pomodori Pachino, Zucchine | Q11: =if(SUMIF( 'TOTALI PIZZE'!A:A,D11,'TOTALI PIZZE'!B:B)=0,"NEW","")
B12: =MIN(SUMIF(INGREDIENTI!$B$2:$B$114,E12,INGREDIENTI!$D$2:$D$114),SUMIF(INGREDIENTI!$B$2:$B$114,F12,INGREDIENTI!$D$2:$D$114),SUMIF(INGREDIENTI!$B$2:$B$114,G12,INGREDIENTI!$D$2:$D$114),SUMIF(INGREDIENTI!$B$2:$B$114,H12,INGREDIENTI!$D$2:$D$114),SUMIF(INGREDIENTI!$B$2:$B$114,I12,INGREDIENTI!$D$2:$D$114),SUMIF(INGREDIENTI!$B$2:$B$114,J12,INGREDIENTI!$D$2:$D$114),SUMIF(INGREDIENTI!$B$2:$B$114,K12,INGREDIENTI!$D$2:$D$114),SUMIF(INGREDIENTI!$B$2:$B$114,L12,INGREDIENTI!$D$2:$D$114)) -> 0 | C12: Speciale | D12: IL FATTORE IGNARO | E12: - | F12: - | G12: Taleggio | H12: Speck | I12: Pere * | J12: Noci * | K12: Pepe * | L12: - | M12: =IF(A12> 0,"SI",IF(B12> 0,"SI","")) | O12: =SUMIF( 'TOTALI PIZZE'!A:A,D12,'TOTALI PIZZE'!B:B) -> 2 | P12: Taleggio, Pere, Speck, Noci, Pepe nero | Q12: =if(SUMIF( 'TOTALI PIZZE'!A:A,D12,'TOTALI PIZZE'!B:B)=0,"NEW","")
B13: =MIN(SUMIF(INGREDIENTI!$B$2:$B$114,E13,INGREDIENTI!$D$2:$D$114),SUMIF(INGREDIENTI!$B$2:$B$114,F13,INGREDIENTI!$D$2:$D$114),SUMIF(INGREDIENTI!$B$2:$B$114,G13,INGREDIENTI!$D$2:$D$114),SUMIF(INGREDIENTI!$B$2:$B$114,H13,INGREDIENTI!$D$2:$D$114),SUMIF(INGREDIENTI!$B$2:$B$114,I13,INGREDIENTI!$D$2:$D$114),SUMIF(INGREDIENTI!$B$2:$B$114,J13,INGREDIENTI!$D$2:$D$114),SUMIF(INGREDIENTI!$B$2:$B$114,K13,INGREDIENTI!$D$2:$D$114),SUMIF(INGREDIENTI!$B$2:$B$114,L13,INGREDIENTI!$D$2:$D$114)) -> 0 | C13: Speciale | D13: MARINANGURIA | E13: Pomodoro stracotto | F13: - | G13: Pomodorini confit | H13: Origano * | I13: Emulsione di aglio nero * | J13: Peperoncino | K13: Basilico * | L13: - | M13: =IF(A13> 0,"SI",IF(B13> 0,"SI","")) | O13: =SUMIF( 'TOTALI PIZZE'!A:A,D13,'TOTALI PIZZE'!B:B) -> 9 | P13: Stracotto di pomodoro, Pomodorini Confit, Origano, Emulsione di aglio nero, Peperoncino | Q13: =if(SUMIF( 'TOTALI PIZZE'!A:A,D13,'TOTALI PIZZE'!B:B)=0,"NEW","")
B14: =MIN(SUMIF(INGREDIENTI!$B$2:$B$114,E14,INGREDIENTI!$D$2:$D$114),SUMIF(INGREDIENTI!$B$2:$B$114,F14,INGREDIENTI!$D$2:$D$114),SUMIF(INGREDIENTI!$B$2:$B$114,G14,INGREDIENTI!$D$2:$D$114),SUMIF(INGREDIENTI!$B$2:$B$114,H14,INGREDIENTI!$D$2:$D$114),SUMIF(INGREDIENTI!$B$2:$B$114,I14,INGREDIENTI!$D$2:$D$114),SUMIF(INGREDIENTI!$B$2:$B$114,J14,INGREDIENTI!$D$2:$D$114),SUMIF(INGREDIENTI!$B$2:$B$114,K14,INGREDIENTI!$D$2:$D$114),SUMIF(INGREDIENTI!$B$2:$B$114,L14,INGREDIENTI!$D$2:$D$114)) -> 0 | C14: Speciale | D14: SUSHI ROLL | E14: - | F14: - | G14: Salmone * | H14: Guacamole * | I14: Semi di sesamo tostati | J14: Maionese al wasabi * | K14: - | L14: - | M14: =IF(A14> 0,"SI",IF(B14> 0,"SI","")) | O14: =SUMIF( 'TOTALI PIZZE'!A:A,D14,'TOTALI PIZZE'!B:B) -> 0 | P14: Salmone, Avocado, Semi di sesamo tostati, maionese al wasabi | Q14: =if(SUMIF( 'TOTALI PIZZE'!A:A,D14,'TOTALI PIZZE'!B:B)=0,"NEW","") -> NEW
B15: =MIN(SUMIF(INGREDIENTI!$B$2:$B$114,E15,INGREDIENTI!$D$2:$D$114),SUMIF(INGREDIENTI!$B$2:$B$114,F15,INGREDIENTI!$D$2:$D$114),SUMIF(INGREDIENTI!$B$2:$B$114,G15,INGREDIENTI!$D$2:$D$114),SUMIF(INGREDIENTI!$B$2:$B$114,H15,INGREDIENTI!$D$2:$D$114),SUMIF(INGREDIENTI!$B$2:$B$114,I15,INGREDIENTI!$D$2:$D$114),SUMIF(INGREDIENTI!$B$2:$B$114,J15,INGREDIENTI!$D$2:$D$114),SUMIF(INGREDIENTI!$B$2:$B$114,K15,INGREDIENTI!$D$2:$D$114),SUMIF(INGREDIENTI!$B$2:$B$114,L15,INGREDIENTI!$D$2:$D$114)) -> 0 | C15: Speciale | D15: PAELLA | E15: Pomodoro | F15: - | G15: Misto Pesce paella | H15: Salsa aioli * | I15: - | J15: - | K15: - | L15: - | M15: =IF(A15> 0,"SI",IF(B15> 0,"SI","")) | O15: =SUMIF( 'TOTALI PIZZE'!A:A,D15,'TOTALI PIZZE'!B:B) -> 0 | P15: Gamberi, Cozze, Zafferano, Salsa aioli | Q15: =if(SUMIF( 'TOTALI PIZZE'!A:A,D15,'TOTALI PIZZE'!B:B)=0,"NEW","") -> NEW
B16: =MIN(SUMIF(INGREDIENTI!$B$2:$B$114,E16,INGREDIENTI!$D$2:$D$114),SUMIF(INGREDIENTI!$B$2:$B$114,F16,INGREDIENTI!$D$2:$D$114),SUMIF(INGREDIENTI!$B$2:$B$114,G16,INGREDIENTI!$D$2:$D$114),SUMIF(INGREDIENTI!$B$2:$B$114,H16,INGREDIENTI!$D$2:$D$114),SUMIF(INGREDIENTI!$B$2:$B$114,I16,INGREDIENTI!$D$2:$D$114),SUMIF(INGREDIENTI!$B$2:$B$114,J16,INGREDIENTI!$D$2:$D$114),SUMIF(INGREDIENTI!$B$2:$B$114,K16,INGREDIENTI!$D$2:$D$114),SUMIF(INGREDIENTI!$B$2:$B$114,L16,INGREDIENTI!$D$2:$D$114)) -> 0 | C16: Speciale | D16: BOEUF BOURGUIGNONNE | E16: - | F16: - | G16: Fontina da fonduta | H16: Stracotto di manzo * | I16: Funghi | J16: Cipolla caramellata | K16: Pepe * | L16: - | M16: =IF(A16> 0,"SI",IF(B16> 0,"SI","")) | O16: =SUMIF( 'TOTALI PIZZE'!A:A,D16,'TOTALI PIZZE'!B:B) -> 0 | P16: Fonduta, Stracotto di Manzo, Funghi, Cipolla caramellata | Q16: =if(SUMIF( 'TOTALI PIZZE'!A:A,D16,'TOTALI PIZZE'!B:B)=0,"NEW","") -> NEW
B17: =MIN(SUMIF(INGREDIENTI!$B$2:$B$114,E17,INGREDIENTI!$D$2:$D$114),SUMIF(INGREDIENTI!$B$2:$B$114,F17,INGREDIENTI!$D$2:$D$114),SUMIF(INGREDIENTI!$B$2:$B$114,G17,INGREDIENTI!$D$2:$D$114),SUMIF(INGREDIENTI!$B$2:$B$114,H17,INGREDIENTI!$D$2:$D$114),SUMIF(INGREDIENTI!$B$2:$B$114,I17,INGREDIENTI!$D$2:$D$114),SUMIF(INGREDIENTI!$B$2:$B$114,J17,INGREDIENTI!$D$2:$D$114),SUMIF(INGREDIENTI!$B$2:$B$114,K17,INGREDIENTI!$D$2:$D$114),SUMIF(INGREDIENTI!$B$2:$B$114,L17,INGREDIENTI!$D$2:$D$114)) -> 0 | C17: Speciale | D17: PIZZOCCHERA | E17: - | F17: - | G17: Bitto o Casera | H17: Verza e Patate | I17: Chips di grano saraceno * | J17: - | K17: - | L17: - | M17: =IF(A17> 0,"SI",IF(B17> 0,"SI","")) | O17: =SUMIF( 'TOTALI PIZZE'!A:A,D17,'TOTALI PIZZE'!B:B) -> 0 | P17: Casera, Patate, Verza, Chips di grano saraceno | Q17: =if(SUMIF( 'TOTALI PIZZE'!A:A,D17,'TOTALI PIZZE'!B:B)=0,"NEW","") -> NEW
B18: =MIN(SUMIF(INGREDIENTI!$B$2:$B$114,E18,INGREDIENTI!$D$2:$D$114),SUMIF(INGREDIENTI!$B$2:$B$114,F18,INGREDIENTI!$D$2:$D$114),SUMIF(INGREDIENTI!$B$2:$B$114,G18,INGREDIENTI!$D$2:$D$114),SUMIF(INGREDIENTI!$B$2:$B$114,H18,INGREDIENTI!$D$2:$D$114),SUMIF(INGREDIENTI!$B$2:$B$114,I18,INGREDIENTI!$D$2:$D$114),SUMIF(INGREDIENTI!$B$2:$B$114,J18,INGREDIENTI!$D$2:$D$114),SUMIF(INGREDIENTI!$B$2:$B$114,K18,INGREDIENTI!$D$2:$D$114),SUMIF(INGREDIENTI!$B$2:$B$114,L18,INGREDIENTI!$D$2:$D$114)) -> 0 | C18: Speciale | D18: BOLOGNA | E18: Pomodoro | F18: - | G18: Mortadella | H18: Stracciatella * | I18: Salsa di pistacchi * | J18: - | K18: - | L18: - | M18: =IF(A18> 0,"SI",IF(B18> 0,"SI","")) | O18: =SUMIF( 'TOTALI PIZZE'!A:A,D18,'TOTALI PIZZE'!B:B) -> 1 | Q18: =if(SUMIF( 'TOTALI PIZZE'!A:A,D18,'TOTALI PIZZE'!B:B)=0,"NEW","")
B19: =MIN(SUMIF(INGREDIENTI!$B$2:$B$114,E19,INGREDIENTI!$D$2:$D$114),SUMIF(INGREDIENTI!$B$2:$B$114,F19,INGREDIENTI!$D$2:$D$114),SUMIF(INGREDIENTI!$B$2:$B$114,G19,INGREDIENTI!$D$2:$D$114),SUMIF(INGREDIENTI!$B$2:$B$114,H19,INGREDIENTI!$D$2:$D$114),SUMIF(INGREDIENTI!$B$2:$B$114,I19,INGREDIENTI!$D$2:$D$114),SUMIF(INGREDIENTI!$B$2:$B$114,J19,INGREDIENTI!$D$2:$D$114),SUMIF(INGREDIENTI!$B$2:$B$114,K19,INGREDIENTI!$D$2:$D$114),SUMIF(INGREDIENTI!$B$2:$B$114,L19,INGREDIENTI!$D$2:$D$114)) -> 0 | C19: Speciale | D19: STRACCIABRESAOLA | E19: - | F19: Fiordilatte | G19: Stracciatella * | H19: Bresaola | I19: Scorza di limone * | J19: - | K19: - | L19: - | M19: =IF(A19> 0,"SI",IF(B19> 0,"SI","")) | O19: =SUMIF( 'TOTALI PIZZE'!A:A,D19,'TOTALI PIZZE'!B:B) -> 0 | Q19: =if(SUMIF( 'TOTALI PIZZE'!A:A,D19,'TOTALI PIZZE'!B:B)=0,"NEW","") -> NEW
B20: =MIN(SUMIF(INGREDIENTI!$B$2:$B$114,E20,INGREDIENTI!$D$2:$D$114),SUMIF(INGREDIENTI!$B$2:$B$114,F20,INGREDIENTI!$D$2:$D$114),SUMIF(INGREDIENTI!$B$2:$B$114,G20,INGREDIENTI!$D$2:$D$114),SUMIF(INGREDIENTI!$B$2:$B$114,H20,INGREDIENTI!$D$2:$D$114),SUMIF(INGREDIENTI!$B$2:$B$114,I20,INGREDIENTI!$D$2:$D$114),SUMIF(INGREDIENTI!$B$2:$B$114,J20,INGREDIENTI!$D$2:$D$114),SUMIF(INGREDIENTI!$B$2:$B$114,K20,INGREDIENTI!$D$2:$D$114),SUMIF(INGREDIENTI!$B$2:$B$114,L20,INGREDIENTI!$D$2:$D$114)) -> 0 | C20: Speciale | D20: FRIARIELLI | E20: Pomodoro | F20: Fiordilatte | G20: Salsiccia | H20: Friarielli | I20: Pepe * | J20: - | K20: - | L20: - | M20: =IF(A20> 0,"SI",IF(B20> 0,"SI","")) | O20: =SUMIF( 'TOTALI PIZZE'!A:A,D20,'TOTALI PIZZE'!B:B) -> 0 | Q20: =if(SUMIF( 'TOTALI PIZZE'!A:A,D20,'TOTALI PIZZE'!B:B)=0,"NEW","") -> NEW
B21: =MIN(SUMIF(INGREDIENTI!$B$2:$B$114,E21,INGREDIENTI!$D$2:$D$114),SUMIF(INGREDIENTI!$B$2:$B$114,F21,INGREDIENTI!$D$2:$D$114),SUMIF(INGREDIENTI!$B$2:$B$114,G21,INGREDIENTI!$D$2:$D$114),SUMIF(INGREDIENTI!$B$2:$B$114,H21,INGREDIENTI!$D$2:$D$114),SUMIF(INGREDIENTI!$B$2:$B$114,I21,INGREDIENTI!$D$2:$D$114),SUMIF(INGREDIENTI!$B$2:$B$114,J21,INGREDIENTI!$D$2:$D$114),SUMIF(INGREDIENTI!$B$2:$B$114,K21,INGREDIENTI!$D$2:$D$114),SUMIF(INGREDIENTI!$B$2:$B$114,L21,INGREDIENTI!$D$2:$D$114)) -> 0 | C21: Speciale | D21: FIORITA | E21: - | F21: Fiordilatte | G21: Fiori di zucca | H21: Acciughe | I21: Stracciatella * | J21: - | K21: - | L21: - | M21: =IF(A21> 0,"SI",IF(B21> 0,"SI","")) | O21: =SUMIF( 'TOTALI PIZZE'!A:A,D21,'TOTALI PIZZE'!B:B) -> 2 | P21: Fiordilatte, Fiori di Zucca, Acciughe. In uscita: Stracciatella di Burrata | Q21: =if(SUMIF( 'TOTALI PIZZE'!A:A,D21,'TOTALI PIZZE'!B:B)=0,"NEW","")
B22: =MIN(SUMIF(INGREDIENTI!$B$2:$B$114,E22,INGREDIENTI!$D$2:$D$114),SUMIF(INGREDIENTI!$B$2:$B$114,F22,INGREDIENTI!$D$2:$D$114),SUMIF(INGREDIENTI!$B$2:$B$114,G22,INGREDIENTI!$D$2:$D$114),SUMIF(INGREDIENTI!$B$2:$B$114,H22,INGREDIENTI!$D$2:$D$114),SUMIF(INGREDIENTI!$B$2:$B$114,I22,INGREDIENTI!$D$2:$D$114),SUMIF(INGREDIENTI!$B$2:$B$114,J22,INGREDIENTI!$D$2:$D$114),SUMIF(INGREDIENTI!$B$2:$B$114,K22,INGREDIENTI!$D$2:$D$114),SUMIF(INGREDIENTI!$B$2:$B$114,L22,INGREDIENTI!$D$2:$D$114)) -> 0 | C22: Speciale | D22: ANATRA&ARANCIA | E22: - | F22: Fiordilatte | G22: Anatra * | H22: Scorzette di arancia * | I22: Pepe * | J22: - | K22: - | L22: - | M22: =IF(A22> 0,"SI",IF(B22> 0,"SI","")) | O22: =SUMIF( 'TOTALI PIZZE'!A:A,D22,'TOTALI PIZZE'!B:B) -> 0 | Q22: =if(SUMIF( 'TOTALI PIZZE'!A:A,D22,'TOTALI PIZZE'!B:B)=0,"NEW","") -> NEW
B23: =MIN(SUMIF(INGREDIENTI!$B$2:$B$114,E23,INGREDIENTI!$D$2:$D$114),SUMIF(INGREDIENTI!$B$2:$B$114,F23,INGREDIENTI!$D$2:$D$114),SUMIF(INGREDIENTI!$B$2:$B$114,G23,INGREDIENTI!$D$2:$D$114),SUMIF(INGREDIENTI!$B$2:$B$114,H23,INGREDIENTI!$D$2:$D$114),SUMIF(INGREDIENTI!$B$2:$B$114,I23,INGREDIENTI!$D$2:$D$114),SUMIF(INGREDIENTI!$B$2:$B$114,J23,INGREDIENTI!$D$2:$D$114),SUMIF(INGREDIENTI!$B$2:$B$114,K23,INGREDIENTI!$D$2:$D$114),SUMIF(INGREDIENTI!$B$2:$B$114,L23,INGREDIENTI!$D$2:$D$114)) -> 0 | C23: Speciale | D23: ALICI E BURRATA | E23: - | F23: - | G23: Pomod.Pachino | H23: Origano * | I23: Stracciatella * | J23: Acciughe | K23: Scorza di limone * | L23: - | M23: =IF(A23> 0,"SI",IF(B23> 0,"SI","")) | O23: =SUMIF( 'TOTALI PIZZE'!A:A,D23,'TOTALI PIZZE'!B:B) -> 0 | Q23: =if(SUMIF( 'TOTALI PIZZE'!A:A,D23,'TOTALI PIZZE'!B:B)=0,"NEW","") -> NEW
B24: =MIN(SUMIF(INGREDIENTI!$B$2:$B$114,E24,INGREDIENTI!$D$2:$D$114),SUMIF(INGREDIENTI!$B$2:$B$114,F24,INGREDIENTI!$D$2:$D$114),SUMIF(INGREDIENTI!$B$2:$B$114,G24,INGREDIENTI!$D$2:$D$114),SUMIF(INGREDIENTI!$B$2:$B$114,H24,INGREDIENTI!$D$2:$D$114),SUMIF(INGREDIENTI!$B$2:$B$114,I24,INGREDIENTI!$D$2:$D$114),SUMIF(INGREDIENTI!$B$2:$B$114,J24,INGREDIENTI!$D$2:$D$114),SUMIF(INGREDIENTI!$B$2:$B$114,K24,INGREDIENTI!$D$2:$D$114),SUMIF(INGREDIENTI!$B$2:$B$114,L24,INGREDIENTI!$D$2:$D$114)) -> 0 | C24: Speciale | D24: STRACCIACRUDO | E24: Pomodoro | F24: Fiordilatte | G24: Stracciatella * | H24: Crudo * | I24: - | J24: - | K24: - | L24: - | M24: =IF(A24> 0,"SI",IF(B24> 0,"SI","")) | O24: =SUMIF( 'TOTALI PIZZE'!A:A,D24,'TOTALI PIZZE'!B:B) -> 0 | Q24: =if(SUMIF( 'TOTALI PIZZE'!A:A,D24,'TOTALI PIZZE'!B:B)=0,"NEW","") -> NEW
B25: =MIN(SUMIF(INGREDIENTI!$B$2:$B$114,E25,INGREDIENTI!$D$2:$D$114),SUMIF(INGREDIENTI!$B$2:$B$114,F25,INGREDIENTI!$D$2:$D$114),SUMIF(INGREDIENTI!$B$2:$B$114,G25,INGREDIENTI!$D$2:$D$114),SUMIF(INGREDIENTI!$B$2:$B$114,H25,INGREDIENTI!$D$2:$D$114),SUMIF(INGREDIENTI!$B$2:$B$114,I25,INGREDIENTI!$D$2:$D$114),SUMIF(INGREDIENTI!$B$2:$B$114,J25,INGREDIENTI!$D$2:$D$114),SUMIF(INGREDIENTI!$B$2:$B$114,K25,INGREDIENTI!$D$2:$D$114),SUMIF(INGREDIENTI!$B$2:$B$114,L25,INGREDIENTI!$D$2:$D$114)) -> 0 | C25: Speciale | D25: POLPOSA | E25: Pomodoro stracotto | F25: - | G25: Polpo | H25: Olive verdi | I25: Prezzemolo | J25: Origano * | K25: - | L25: - | M25: =IF(A25> 0,"SI",IF(B25> 0,"SI","")) | O25: =SUMIF( 'TOTALI PIZZE'!A:A,D25,'TOTALI PIZZE'!B:B) -> 1 | P25: Rossa con Polpo, Olive verdi, Origano e prezzemolo | Q25: =if(SUMIF( 'TOTALI PIZZE'!A:A,D25,'TOTALI PIZZE'!B:B)=0,"NEW","")
B26: =MIN(SUMIF(INGREDIENTI!$B$2:$B$114,E26,INGREDIENTI!$D$2:$D$114),SUMIF(INGREDIENTI!$B$2:$B$114,F26,INGREDIENTI!$D$2:$D$114),SUMIF(INGREDIENTI!$B$2:$B$114,G26,INGREDIENTI!$D$2:$D$114),SUMIF(INGREDIENTI!$B$2:$B$114,H26,INGREDIENTI!$D$2:$D$114),SUMIF(INGREDIENTI!$B$2:$B$114,I26,INGREDIENTI!$D$2:$D$114),SUMIF(INGREDIENTI!$B$2:$B$114,J26,INGREDIENTI!$D$2:$D$114),SUMIF(INGREDIENTI!$B$2:$B$114,K26,INGREDIENTI!$D$2:$D$114),SUMIF(INGREDIENTI!$B$2:$B$114,L26,INGREDIENTI!$D$2:$D$114)) -> 0 | C26: Speciale | D26: METATO | E26: - | F26: - | G26: Provola affumicata | H26: Funghi | I26: Crema di castagne * | J26: Rosmarino | K26: - | L26: - | M26: =IF(A26> 0,"SI",IF(B26> 0,"SI","")) | O26: =SUMIF( 'TOTALI PIZZE'!A:A,D26,'TOTALI PIZZE'!B:B) -> 1 | P26: Provola affumicata, Porcini, Crema di castagne, Rosmarino | Q26: =if(SUMIF( 'TOTALI PIZZE'!A:A,D26,'TOTALI PIZZE'!B:B)=0,"NEW","")
B27: =MIN(SUMIF(INGREDIENTI!$B$2:$B$114,E27,INGREDIENTI!$D$2:$D$114),SUMIF(INGREDIENTI!$B$2:$B$114,F27,INGREDIENTI!$D$2:$D$114),SUMIF(INGREDIENTI!$B$2:$B$114,G27,INGREDIENTI!$D$2:$D$114),SUMIF(INGREDIENTI!$B$2:$B$114,H27,INGREDIENTI!$D$2:$D$114),SUMIF(INGREDIENTI!$B$2:$B$114,I27,INGREDIENTI!$D$2:$D$114),SUMIF(INGREDIENTI!$B$2:$B$114,J27,INGREDIENTI!$D$2:$D$114),SUMIF(INGREDIENTI!$B$2:$B$114,K27,INGREDIENTI!$D$2:$D$114),SUMIF(INGREDIENTI!$B$2:$B$114,L27,INGREDIENTI!$D$2:$D$114)) -> 0 | C27: Speciale | D27: SALTALFUNGO | E27: Pomodoro | F27: - | G27: Taleggio | H27: Funghi | I27: Salsiccia | J27: Pepe * | K27: - | L27: - | M27: =IF(A27> 0,"SI",IF(B27> 0,"SI","")) | O27: =SUMIF( 'TOTALI PIZZE'!A:A,D27,'TOTALI PIZZE'!B:B) -> 1 | P27: Salsiccia, Taleggio, Porcini, Pepe nero | Q27: =if(SUMIF( 'TOTALI PIZZE'!A:A,D27,'TOTALI PIZZE'!B:B)=0,"NEW","")
B28: =MIN(SUMIF(INGREDIENTI!$B$2:$B$114,E28,INGREDIENTI!$D$2:$D$114),SUMIF(INGREDIENTI!$B$2:$B$114,F28,INGREDIENTI!$D$2:$D$114),SUMIF(INGREDIENTI!$B$2:$B$114,G28,INGREDIENTI!$D$2:$D$114),SUMIF(INGREDIENTI!$B$2:$B$114,H28,INGREDIENTI!$D$2:$D$114),SUMIF(INGREDIENTI!$B$2:$B$114,I28,INGREDIENTI!$D$2:$D$114),SUMIF(INGREDIENTI!$B$2:$B$114,J28,INGREDIENTI!$D$2:$D$114),SUMIF(INGREDIENTI!$B$2:$B$114,K28,INGREDIENTI!$D$2:$D$114),SUMIF(INGREDIENTI!$B$2:$B$114,L28,INGREDIENTI!$D$2:$D$114)) -> 0 | C28: Classica | D28: STRACAPOECOLLO | E28: Pomodoro stracotto | F28: Fiordilatte | G28: Carciofini | H28: Capocollo | I28: - | J28: - | K28: - | L28: - | M28: =IF(A28> 0,"SI",IF(B28> 0,"SI","")) | O28: =SUMIF( 'TOTALI PIZZE'!A:A,D28,'TOTALI PIZZE'!B:B) -> 1 | P28: Stracotto di pomodoro, Fiordilatte, Carciofini, Capocollo | Q28: =if(SUMIF( 'TOTALI PIZZE'!A:A,D28,'TOTALI PIZZE'!B:B)=0,"NEW","")
B29: =MIN(SUMIF(INGREDIENTI!$B$2:$B$114,E29,INGREDIENTI!$D$2:$D$114),SUMIF(INGREDIENTI!$B$2:$B$114,F29,INGREDIENTI!$D$2:$D$114),SUMIF(INGREDIENTI!$B$2:$B$114,G29,INGREDIENTI!$D$2:$D$114),SUMIF(INGREDIENTI!$B$2:$B$114,H29,INGREDIENTI!$D$2:$D$114),SUMIF(INGREDIENTI!$B$2:$B$114,I29,INGREDIENTI!$D$2:$D$114),SUMIF(INGREDIENTI!$B$2:$B$114,J29,INGREDIENTI!$D$2:$D$114),SUMIF(INGREDIENTI!$B$2:$B$114,K29,INGREDIENTI!$D$2:$D$114),SUMIF(INGREDIENTI!$B$2:$B$114,L29,INGREDIENTI!$D$2:$D$114)) -> 0 | C29: Classica | D29: PICCANTOLA | E29: - | F29: Fiordilatte | G29: Gorgonzola | H29: Salame piccante | I29: Miele * | J29: - | K29: - | L29: - | M29: =IF(A29> 0,"SI",IF(B29> 0,"SI","")) | O29: =SUMIF( 'TOTALI PIZZE'!A:A,D29,'TOTALI PIZZE'!B:B) -> 1 | P29: Bianca con Gorgonzola, Miele e Salame piccante | Q29: =if(SUMIF( 'TOTALI PIZZE'!A:A,D29,'TOTALI PIZZE'!B:B)=0,"NEW","")
B30: =MIN(SUMIF(INGREDIENTI!$B$2:$B$114,E30,INGREDIENTI!$D$2:$D$114),SUMIF(INGREDIENTI!$B$2:$B$114,F30,INGREDIENTI!$D$2:$D$114),SUMIF(INGREDIENTI!$B$2:$B$114,G30,INGREDIENTI!$D$2:$D$114),SUMIF(INGREDIENTI!$B$2:$B$114,H30,INGREDIENTI!$D$2:$D$114),SUMIF(INGREDIENTI!$B$2:$B$114,I30,INGREDIENTI!$D$2:$D$114),SUMIF(INGREDIENTI!$B$2:$B$114,J30,INGREDIENTI!$D$2:$D$114),SUMIF(INGREDIENTI!$B$2:$B$114,K30,INGREDIENTI!$D$2:$D$114),SUMIF(INGREDIENTI!$B$2:$B$114,L30,INGREDIENTI!$D$2:$D$114)) -> 0 | C30: Speciale | D30: SPECCASTAGNA | E30: - | F30: - | G30: Provola affumicata | H30: Speck | I30: Crema di castagne * | J30: - | K30: - | L30: - | M30: =IF(A30> 0,"SI",IF(B30> 0,"SI","")) | O30: =SUMIF( 'TOTALI PIZZE'!A:A,D30,'TOTALI PIZZE'!B:B) -> 0 | P30: Provola affumicata, Speck, Crema di castagne | Q30: =if(SUMIF( 'TOTALI PIZZE'!A:A,D30,'TOTALI PIZZE'!B:B)=0,"NEW","") -> NEW
B31: =MIN(SUMIF(INGREDIENTI!$B$2:$B$114,E31,INGREDIENTI!$D$2:$D$114),SUMIF(INGREDIENTI!$B$2:$B$114,F31,INGREDIENTI!$D$2:$D$114),SUMIF(INGREDIENTI!$B$2:$B$114,G31,INGREDIENTI!$D$2:$D$114),SUMIF(INGREDIENTI!$B$2:$B$114,H31,INGREDIENTI!$D$2:$D$114),SUMIF(INGREDIENTI!$B$2:$B$114,I31,INGREDIENTI!$D$2:$D$114),SUMIF(INGREDIENTI!$B$2:$B$114,J31,INGREDIENTI!$D$2:$D$114),SUMIF(INGREDIENTI!$B$2:$B$114,K31,INGREDIENTI!$D$2:$D$114),SUMIF(INGREDIENTI!$B$2:$B$114,L31,INGREDIENTI!$D$2:$D$114)) -> 0 | C31: Speciale | D31: CECIECOZZE | E31: Pomodoro | F31: - | G31: Cozze | H31: Crema di ceci * | I31: Pepe * | J31: - | K31: - | L31: - | M31: =IF(A31> 0,"SI",IF(B31> 0,"SI","")) | O31: =SUMIF( 'TOTALI PIZZE'!A:A,D31,'TOTALI PIZZE'!B:B) -> 0 | P31: Rossa con Cozze e Pepe. In uscita Crema di Ceci | Q31: =if(SUMIF( 'TOTALI PIZZE'!A:A,D31,'TOTALI PIZZE'!B:B)=0,"NEW","") -> NEW
B32: =MIN(SUMIF(INGREDIENTI!$B$2:$B$114,E32,INGREDIENTI!$D$2:$D$114),SUMIF(INGREDIENTI!$B$2:$B$114,F32,INGREDIENTI!$D$2:$D$114),SUMIF(INGREDIENTI!$B$2:$B$114,G32,INGREDIENTI!$D$2:$D$114),SUMIF(INGREDIENTI!$B$2:$B$114,H32,INGREDIENTI!$D$2:$D$114),SUMIF(INGREDIENTI!$B$2:$B$114,I32,INGREDIENTI!$D$2:$D$114),SUMIF(INGREDIENTI!$B$2:$B$114,J32,INGREDIENTI!$D$2:$D$114),SUMIF(INGREDIENTI!$B$2:$B$114,K32,INGREDIENTI!$D$2:$D$114),SUMIF(INGREDIENTI!$B$2:$B$114,L32,INGREDIENTI!$D$2:$D$114)) -> 0 | C32: Speciale | D32: AVOCADOTOAST | E32: - | F32: - | G32: Provola affumicata | H32: Guacamole * | I32: Salmone * | J32: Uova strapazzate * | K32: Pepe * | L32: - | M32: =IF(A32> 0,"SI",IF(B32> 0,"SI","")) | O32: =SUMIF( 'TOTALI PIZZE'!A:A,D32,'TOTALI PIZZE'!B:B) -> 2 | P32: Guacamole, Salmone, Provola, Uovo strapazzato, Pepe | Q32: =if(SUMIF( 'TOTALI PIZZE'!A:A,D32,'TOTALI PIZZE'!B:B)=0,"NEW","")
B33: =MIN(SUMIF(INGREDIENTI!$B$2:$B$114,E33,INGREDIENTI!$D$2:$D$114),SUMIF(INGREDIENTI!$B$2:$B$114,F33,INGREDIENTI!$D$2:$D$114),SUMIF(INGREDIENTI!$B$2:$B$114,G33,INGREDIENTI!$D$2:$D$114),SUMIF(INGREDIENTI!$B$2:$B$114,H33,INGREDIENTI!$D$2:$D$114),SUMIF(INGREDIENTI!$B$2:$B$114,I33,INGREDIENTI!$D$2:$D$114),SUMIF(INGREDIENTI!$B$2:$B$114,J33,INGREDIENTI!$D$2:$D$114),SUMIF(INGREDIENTI!$B$2:$B$114,K33,INGREDIENTI!$D$2:$D$114),SUMIF(INGREDIENTI!$B$2:$B$114,L33,INGREDIENTI!$D$2:$D$114)) -> 0 | C33: Classica | D33: BUFALA&CRUDO | E33: Pomodoro | F33: Fiordilatte | G33: Bufala | H33: Crudo * | I33: - | J33: - | K33: - | L33: - | M33: =IF(A33> 0,"SI",IF(B33> 0,"SI","")) | O33: =SUMIF( 'TOTALI PIZZE'!A:A,D33,'TOTALI PIZZE'!B:B) -> 2 | P33: Tradizionale margherita arricchita di Bufala e prosciutto crudo | Q33: =if(SUMIF( 'TOTALI PIZZE'!A:A,D33,'TOTALI PIZZE'!B:B)=0,"NEW","")
B34: =MIN(SUMIF(INGREDIENTI!$B$2:$B$114,E34,INGREDIENTI!$D$2:$D$114),SUMIF(INGREDIENTI!$B$2:$B$114,F34,INGREDIENTI!$D$2:$D$114),SUMIF(INGREDIENTI!$B$2:$B$114,G34,INGREDIENTI!$D$2:$D$114),SUMIF(INGREDIENTI!$B$2:$B$114,H34,INGREDIENTI!$D$2:$D$114),SUMIF(INGREDIENTI!$B$2:$B$114,I34,INGREDIENTI!$D$2:$D$114),SUMIF(INGREDIENTI!$B$2:$B$114,J34,INGREDIENTI!$D$2:$D$114),SUMIF(INGREDIENTI!$B$2:$B$114,K34,INGREDIENTI!$D$2:$D$114),SUMIF(INGREDIENTI!$B$2:$B$114,L34,INGREDIENTI!$D$2:$D$114)) -> 0 | C34: Speciale | D34: FIRENZE | E34: Pomodoro | F34: Fiordilatte | G34: Crema di pecorino | H34: Finocchiona | I34: Carciofini | J34: - | K34: - | L34: - | M34: =IF(A34> 0,"SI",IF(B34> 0,"SI","")) | O34: =SUMIF( 'TOTALI PIZZE'!A:A,D34,'TOTALI PIZZE'!B:B) -> 1 | P34: Rossa con crema di pecorino, Finocchiona e carciofini | Q34: =if(SUMIF( 'TOTALI PIZZE'!A:A,D34,'TOTALI PIZZE'!B:B)=0,"NEW","")
B35: =MIN(SUMIF(INGREDIENTI!$B$2:$B$114,E35,INGREDIENTI!$D$2:$D$114),SUMIF(INGREDIENTI!$B$2:$B$114,F35,INGREDIENTI!$D$2:$D$114),SUMIF(INGREDIENTI!$B$2:$B$114,G35,INGREDIENTI!$D$2:$D$114),SUMIF(INGREDIENTI!$B$2:$B$114,H35,INGREDIENTI!$D$2:$D$114),SUMIF(INGREDIENTI!$B$2:$B$114,I35,INGREDIENTI!$D$2:$D$114),SUMIF(INGREDIENTI!$B$2:$B$114,J35,INGREDIENTI!$D$2:$D$114),SUMIF(INGREDIENTI!$B$2:$B$114,K35,INGREDIENTI!$D$2:$D$114),SUMIF(INGREDIENTI!$B$2:$B$114,L35,INGREDIENTI!$D$2:$D$114)) -> 0 | C35: Speciale | D35: GAMBERI&MANGO | E35: - | F35: Fiordilatte | G35: Pomod.Pachino | H35: Gamberi rossi * | I35: Salsa al mango * | J35: - | K35: - | L35: - | M35: =IF(A35> 0,"SI",IF(B35> 0,"SI","")) | O35: =SUMIF( 'TOTALI PIZZE'!A:A,D35,'TOTALI PIZZE'!B:B) -> 1 | P35: Fiordilatte, Gamberi, Pomodirini Pachino e Salsa al Mango | Q35: =if(SUMIF( 'TOTALI PIZZE'!A:A,D35,'TOTALI PIZZE'!B:B)=0,"NEW","")
B36: =MIN(SUMIF(INGREDIENTI!$B$2:$B$114,E36,INGREDIENTI!$D$2:$D$114),SUMIF(INGREDIENTI!$B$2:$B$114,F36,INGREDIENTI!$D$2:$D$114),SUMIF(INGREDIENTI!$B$2:$B$114,G36,INGREDIENTI!$D$2:$D$114),SUMIF(INGREDIENTI!$B$2:$B$114,H36,INGREDIENTI!$D$2:$D$114),SUMIF(INGREDIENTI!$B$2:$B$114,I36,INGREDIENTI!$D$2:$D$114),SUMIF(INGREDIENTI!$B$2:$B$114,J36,INGREDIENTI!$D$2:$D$114),SUMIF(INGREDIENTI!$B$2:$B$114,K36,INGREDIENTI!$D$2:$D$114),SUMIF(INGREDIENTI!$B$2:$B$114,L36,INGREDIENTI!$D$2:$D$114)) -> 0 | C36: Speciale | D36: PISELLINA | E36: - | F36: Fiordilatte | G36: Pancetta * | H36: Uova strapazzate * | I36: Crema di piselli * | J36: - | K36: - | L36: - | M36: =IF(A36> 0,"SI",IF(B36> 0,"SI","")) | O36: =SUMIF( 'TOTALI PIZZE'!A:A,D36,'TOTALI PIZZE'!B:B) -> 7 | P36: Base fiordilatte. In uscita: Crema di piselli, Pancetta, Uova strapazzate | Q36: =if(SUMIF( 'TOTALI PIZZE'!A:A,D36,'TOTALI PIZZE'!B:B)=0,"NEW","")
... B57: =MIN(SUMIF(INGREDIENTI!$B$2:$B$114,E57,INGREDIENTI!$D$2:$D$114),SUMIF(INGREDIENTI!$B$2:$B$114,F57,INGREDIENTI!$D$2:$D$114),SUMIF(INGREDIENTI!$B$2:$B$114,G57,INGREDIENTI!$D$2:$D$114),SUMIF(INGREDIENTI!$B$2:$B$114,H57,INGREDIENTI!$D$2:$D$114),SUMIF(INGREDIENTI!$B$2:$B$114,I57,INGREDIENTI!$D$2:$D$114),SUMIF(INGREDIENTI!$B$2:$B$114,J57,INGREDIENTI!$D$2:$D$114),SUMIF(INGREDIENTI!$B$2:$B$114,K57,INGREDIENTI!$D$2:$D$114),SUMIF(INGREDIENTI!$B$2:$B$114,L57,INGREDIENTI!$D$2:$D$114)) -> 0 | C57: Classica | D57: BUFALINA | E57: Pomodoro | F57: - | G57: Bufala | H57: Pomod.Pachino | I57: Basilico * | J57: - | K57: - | L57: - | M57: =IF(A57> 0,"SI",IF(B57> 0,"SI","")) | O57: =SUMIF( 'TOTALI PIZZE'!A:A,D57,'TOTALI PIZZE'!B:B) -> 1 | P57: Pomodoro, Bufala, Pomodorini pachino, Basilico | Q57: =if(SUMIF( 'TOTALI PIZZE'!A:A,D57,'TOTALI PIZZE'!B:B)=0,"NEW","")
B58: =MIN(SUMIF(INGREDIENTI!$B$2:$B$114,E58,INGREDIENTI!$D$2:$D$114),SUMIF(INGREDIENTI!$B$2:$B$114,F58,INGREDIENTI!$D$2:$D$114),SUMIF(INGREDIENTI!$B$2:$B$114,G58,INGREDIENTI!$D$2:$D$114),SUMIF(INGREDIENTI!$B$2:$B$114,H58,INGREDIENTI!$D$2:$D$114),SUMIF(INGREDIENTI!$B$2:$B$114,I58,INGREDIENTI!$D$2:$D$114),SUMIF(INGREDIENTI!$B$2:$B$114,J58,INGREDIENTI!$D$2:$D$114),SUMIF(INGREDIENTI!$B$2:$B$114,K58,INGREDIENTI!$D$2:$D$114),SUMIF(INGREDIENTI!$B$2:$B$114,L58,INGREDIENTI!$D$2:$D$114)) -> 0 | C58: Speciale | D58: LARDO&BASILICO | E58: Pomodoro | F58: Fiordilatte | G58: Lardo * | H58: Pomod.Pachino | I58: Basilico * | J58: - | K58: - | L58: - | M58: =IF(A58> 0,"SI",IF(B58> 0,"SI","")) | O58: =SUMIF( 'TOTALI PIZZE'!A:A,D58,'TOTALI PIZZE'!B:B) -> 0 | Q58: =if(SUMIF( 'TOTALI PIZZE'!A:A,D58,'TOTALI PIZZE'!B:B)=0,"NEW","") -> NEW
B59: =MIN(SUMIF(INGREDIENTI!$B$2:$B$114,E59,INGREDIENTI!$D$2:$D$114),SUMIF(INGREDIENTI!$B$2:$B$114,F59,INGREDIENTI!$D$2:$D$114),SUMIF(INGREDIENTI!$B$2:$B$114,G59,INGREDIENTI!$D$2:$D$114),SUMIF(INGREDIENTI!$B$2:$B$114,H59,INGREDIENTI!$D$2:$D$114),SUMIF(INGREDIENTI!$B$2:$B$114,I59,INGREDIENTI!$D$2:$D$114),SUMIF(INGREDIENTI!$B$2:$B$114,J59,INGREDIENTI!$D$2:$D$114),SUMIF(INGREDIENTI!$B$2:$B$114,K59,INGREDIENTI!$D$2:$D$114),SUMIF(INGREDIENTI!$B$2:$B$114,L59,INGREDIENTI!$D$2:$D$114)) -> 0 | C59: Speciale | D59: BOLOGNALMIELE | E59: - | F59: Fiordilatte | G59: Mortadella | H59: Pecorino | I59: Miele * | J59: - | K59: - | L59: - | M59: =IF(A59> 0,"SI",IF(B59> 0,"SI","")) | O59: =SUMIF( 'TOTALI PIZZE'!A:A,D59,'TOTALI PIZZE'!B:B) -> 0 | Q59: =if(SUMIF( 'TOTALI PIZZE'!A:A,D59,'TOTALI PIZZE'!B:B)=0,"NEW","") -> NEW
B60: =MIN(SUMIF(INGREDIENTI!$B$2:$B$114,E60,INGREDIENTI!$D$2:$D$114),SUMIF(INGREDIENTI!$B$2:$B$114,F60,INGREDIENTI!$D$2:$D$114),SUMIF(INGREDIENTI!$B$2:$B$114,G60,INGREDIENTI!$D$2:$D$114),SUMIF(INGREDIENTI!$B$2:$B$114,H60,INGREDIENTI!$D$2:$D$114),SUMIF(INGREDIENTI!$B$2:$B$114,I60,INGREDIENTI!$D$2:$D$114),SUMIF(INGREDIENTI!$B$2:$B$114,J60,INGREDIENTI!$D$2:$D$114),SUMIF(INGREDIENTI!$B$2:$B$114,K60,INGREDIENTI!$D$2:$D$114),SUMIF(INGREDIENTI!$B$2:$B$114,L60,INGREDIENTI!$D$2:$D$114)) -> 0 | C60: Base | D60: MARINARA ++ | E60: Pomodoro | F60: - | G60: Pomod.Pachino | H60: Aglio | I60: Origano * | J60: Basilico * | K60: - | L60: - | M60: =IF(A60> 0,"SI",IF(B60> 0,"SI","")) | O60: =SUMIF( 'TOTALI PIZZE'!A:A,D60,'TOTALI PIZZE'!B:B) -> 0 | Q60: =if(SUMIF( 'TOTALI PIZZE'!A:A,D60,'TOTALI PIZZE'!B:B)=0,"NEW","") -> NEW
B61: =MIN(SUMIF(INGREDIENTI!$B$2:$B$114,E61,INGREDIENTI!$D$2:$D$114),SUMIF(INGREDIENTI!$B$2:$B$114,F61,INGREDIENTI!$D$2:$D$114),SUMIF(INGREDIENTI!$B$2:$B$114,G61,INGREDIENTI!$D$2:$D$114),SUMIF(INGREDIENTI!$B$2:$B$114,H61,INGREDIENTI!$D$2:$D$114),SUMIF(INGREDIENTI!$B$2:$B$114,I61,INGREDIENTI!$D$2:$D$114),SUMIF(INGREDIENTI!$B$2:$B$114,J61,INGREDIENTI!$D$2:$D$114),SUMIF(INGREDIENTI!$B$2:$B$114,K61,INGREDIENTI!$D$2:$D$114),SUMIF(INGREDIENTI!$B$2:$B$114,L61,INGREDIENTI!$D$2:$D$114)) -> 0 | C61: Base | D61: NAPOLI | E61: Pomodoro | F61: Fiordilatte | G61: Acciughe | H61: Capperi | I61: - | J61: - | K61: - | L61: - | M61: =IF(A61> 0,"SI",IF(B61> 0,"SI","")) | O61: =SUMIF( 'TOTALI PIZZE'!A:A,D61,'TOTALI PIZZE'!B:B) -> 1 | Q61: =if(SUMIF( 'TOTALI PIZZE'!A:A,D61,'TOTALI PIZZE'!B:B)=0,"NEW","")
...

Sheet INGREDIENTI
A1: TIPO | B1: INGREDIENTE | C1: QTA' NECESS. (pizze richieste) | D1: Già in casa (pizze realizzabili) | E1: in casa __ | F1: DA ACQUISTARE | G1: QTA' DA ACQUISTARE (Nro pizze) | H1: IN QUANTE PIZZE (totale) | I1: Ingredienti delle preparazioni | K1: Aggiungi ingrediente
A2: 0.ingred.vuoto | B2: - | D2: 1000
A3: __Pomodoro | B3: Pomodoro | C3: =SUMIF('MENU PIZZE'!$E$4:$E$110,B3,'MENU PIZZE'!$A$4:$A$110)+SUMIF('MENU PIZZE'!$F$4:$F$110,B3,'MENU PIZZE'!$A$4:$A$110)+SUMIF('MENU PIZZE'!$G$4:$G$110,B3,'MENU PIZZE'!$A$4:$A$110)+SUMIF('MENU PIZZE'!$H$4:$H$110,B3,'MENU PIZZE'!$A$4:$A$110)+SUMIF('MENU PIZZE'!$I$4:$I$110,B3,'MENU PIZZE'!$A$4:$A$110)+SUMIF('MENU PIZZE'!$J$4:$J$110,B3,'MENU PIZZE'!$A$4:$A$110)+SUMIF('MENU PIZZE'!$K$4:$K$110,B3,'MENU PIZZE'!$A$4:$A$110)+SUMIF('MENU PIZZE'!$L$4:$L$110,B3,'MENU PIZZE'!$A$4:$A$110) -> 2 | E3: =if(AND(D3>0,D3=C3), "SI","") | F3: =IF(G3>0,"SI","") -> SI | G3: =Max(C3-D3,0) -> 2 | H3: =countif('MENU PIZZE'!$E$4:$L$110,B3) -> 49 | I3: =IFERROR(VLOOKUP(B3,'Ricette dei preparati'!B:D,3,FALSE),"")
A4: _Fiordilatte | B4: Fiordilatte | C4: =SUMIF('MENU PIZZE'!$E$4:$E$110,B4,'MENU PIZZE'!$A$4:$A$110)+SUMIF('MENU PIZZE'!$F$4:$F$110,B4,'MENU PIZZE'!$A$4:$A$110)+SUMIF('MENU PIZZE'!$G$4:$G$110,B4,'MENU PIZZE'!$A$4:$A$110)+SUMIF('MENU PIZZE'!$H$4:$H$110,B4,'MENU PIZZE'!$A$4:$A$110)+SUMIF('MENU PIZZE'!$I$4:$I$110,B4,'MENU PIZZE'!$A$4:$A$110)+SUMIF('MENU PIZZE'!$J$4:$J$110,B4,'MENU PIZZE'!$A$4:$A$110)+SUMIF('MENU PIZZE'!$K$4:$K$110,B4,'MENU PIZZE'!$A$4:$A$110)+SUMIF('MENU PIZZE'!$L$4:$L$110,B4,'MENU PIZZE'!$A$4:$A$110) -> 4 | E4: =if(AND(D4>0,D4=C4), "SI","") | F4: =IF(G4>0,"SI","") -> SI | G4: =Max(C4-D4,0) -> 4 | H4: =countif('MENU PIZZE'!$E$4:$L$110,B4) -> 65 | I4: =IFERROR(VLOOKUP(B4,'Ricette dei preparati'!B:D,3,FALSE),"")
A5: 1.Formaggi | B5: Gorgonzola | C5: =SUMIF('MENU PIZZE'!$E$4:$E$110,B5,'MENU PIZZE'!$A$4:$A$110)+SUMIF('MENU PIZZE'!$F$4:$F$110,B5,'MENU PIZZE'!$A$4:$A$110)+SUMIF('MENU PIZZE'!$G$4:$G$110,B5,'MENU PIZZE'!$A$4:$A$110)+SUMIF('MENU PIZZE'!$H$4:$H$110,B5,'MENU PIZZE'!$A$4:$A$110)+SUMIF('MENU PIZZE'!$I$4:$I$110,B5,'MENU PIZZE'!$A$4:$A$110)+SUMIF('MENU PIZZE'!$J$4:$J$110,B5,'MENU PIZZE'!$A$4:$A$110)+SUMIF('MENU PIZZE'!$K$4:$K$110,B5,'MENU PIZZE'!$A$4:$A$110)+SUMIF('MENU PIZZE'!$L$4:$L$110,B5,'MENU PIZZE'!$A$4:$A$110) -> 1 | E5: =if(AND(D5>0,D5=C5), "SI","") | F5: =IF(G5>0,"SI","") -> SI | G5: =Max(C5-D5,0) -> 1 | H5: =countif('MENU PIZZE'!$E$4:$L$110,B5) -> 10 | I5: =IFERROR(VLOOKUP(B5,'Ricette dei preparati'!B:D,3,FALSE),"")
A6: 1.Formaggi | B6: Parmigiano | C6: =SUMIF('MENU PIZZE'!$E$4:$E$110,B6,'MENU PIZZE'!$A$4:$A$110)+SUMIF('MENU PIZZE'!$F$4:$F$110,B6,'MENU PIZZE'!$A$4:$A$110)+SUMIF('MENU PIZZE'!$G$4:$G$110,B6,'MENU PIZZE'!$A$4:$A$110)+SUMIF('MENU PIZZE'!$H$4:$H$110,B6,'MENU PIZZE'!$A$4:$A$110)+SUMIF('MENU PIZZE'!$I$4:$I$110,B6,'MENU PIZZE'!$A$4:$A$110)+SUMIF('MENU PIZZE'!$J$4:$J$110,B6,'MENU PIZZE'!$A$4:$A$110)+SUMIF('MENU PIZZE'!$K$4:$K$110,B6,'MENU PIZZE'!$A$4:$A$110)+SUMIF('MENU PIZZE'!$L$4:$L$110,B6,'MENU PIZZE'!$A$4:$A$110) -> 4 | E6: =if(AND(D6>0,D6=C6), "SI","") | F6: =IF(G6>0,"SI","") -> SI | G6: =Max(C6-D6,0) -> 4 | H6: =countif('MENU PIZZE'!$E$4:$L$110,B6) -> 15 | I6: =IFERROR(VLOOKUP(B6,'Ricette dei preparati'!B:D,3,FALSE),"")
A7: 1.Formaggi | B7: Pecorino | C7: =SUMIF('MENU PIZZE'!$E$4:$E$110,B7,'MENU PIZZE'!$A$4:$A$110)+SUMIF('MENU PIZZE'!$F$4:$F$110,B7,'MENU PIZZE'!$A$4:$A$110)+SUMIF('MENU PIZZE'!$G$4:$G$110,B7,'MENU PIZZE'!$A$4:$A$110)+SUMIF('MENU PIZZE'!$H$4:$H$110,B7,'MENU PIZZE'!$A$4:$A$110)+SUMIF('MENU PIZZE'!$I$4:$I$110,B7,'MENU PIZZE'!$A$4:$A$110)+SUMIF('MENU PIZZE'!$J$4:$J$110,B7,'MENU PIZZE'!$A$4:$A$110)+SUMIF('MENU PIZZE'!$K$4:$K$110,B7,'MENU PIZZE'!$A$4:$A$110)+SUMIF('MENU PIZZE'!$L$4:$L$110,B7,'MENU PIZZE'!$A$4:$A$110) -> 1 | E7: =if(AND(D7>0,D7=C7), "SI","") | F7: =IF(G7>0,"SI","") -> SI | G7: =Max(C7-D7,0) -> 1 | H7: =countif('MENU PIZZE'!$E$4:$L$110,B7) -> 4 | I7: =IFERROR(VLOOKUP(B7,'Ricette dei preparati'!B:D,3,FALSE),"")
A8: 1.Formaggi | B8: Stracciatella * | C8: =SUMIF('MENU PIZZE'!$E$4:$E$110,B8,'MENU PIZZE'!$A$4:$A$110)+SUMIF('MENU PIZZE'!$F$4:$F$110,B8,'MENU PIZZE'!$A$4:$A$110)+SUMIF('MENU PIZZE'!$G$4:$G$110,B8,'MENU PIZZE'!$A$4:$A$110)+SUMIF('MENU PIZZE'!$H$4:$H$110,B8,'MENU PIZZE'!$A$4:$A$110)+SUMIF('MENU PIZZE'!$I$4:$I$110,B8,'MENU PIZZE'!$A$4:$A$110)+SUMIF('MENU PIZZE'!$J$4:$J$110,B8,'MENU PIZZE'!$A$4:$A$110)+SUMIF('MENU PIZZE'!$K$4:$K$110,B8,'MENU PIZZE'!$A$4:$A$110)+SUMIF('MENU PIZZE'!$L$4:$L$110,B8,'MENU PIZZE'!$A$4:$A$110) -> 2 | E8: =if(AND(D8>0,D8=C8), "SI","") | F8: =IF(G8>0,"SI","") -> SI | G8: =Max(C8-D8,0) -> 2 | H8: =countif('MENU PIZZE'!$E$4:$L$110,B8) -> 16 | I8: =IFERROR(VLOOKUP(B8,'Ricette dei preparati'!B:D,3,FALSE),"")
A9: 3.Pesce | B9: Gamberi rossi * | C9: =SUMIF('MENU PIZZE'!$E$4:$E$110,B9,'MENU PIZZE'!$A$4:$A$110)+SUMIF('MENU PIZZE'!$F$4:$F$110,B9,'MENU PIZZE'!$A$4:$A$110)+SUMIF('MENU PIZZE'!$G$4:$G$110,B9,'MENU PIZZE'!$A$4:$A$110)+SUMIF('MENU PIZZE'!$H$4:$H$110,B9,'MENU PIZZE'!$A$4:$A$110)+SUMIF('MENU PIZZE'!$I$4:$I$110,B9,'MENU PIZZE'!$A$4:$A$110)+SUMIF('MENU PIZZE'!$J$4:$J$110,B9,'MENU PIZZE'!$A$4:$A$110)+SUMIF('MENU PIZZE'!$K$4:$K$110,B9,'MENU PIZZE'!$A$4:$A$110)+SUMIF('MENU PIZZE'!$L$4:$L$110,B9,'MENU PIZZE'!$A$4:$A$110) -> 1 | E9: =if(AND(D9>0,D9=C9), "SI","") | F9: =IF(G9>0,"SI","") -> SI | G9: =Max(C9-D9,0) -> 1 | H9: =countif('MENU PIZZE'!$E$4:$L$110,B9) -> 3 | I9: =IFERROR(VLOOKUP(B9,'Ricette dei preparati'!B:D,3,FALSE),"")
A10: 4.Verdure | B10: Basilico * | C10: =SUMIF('MENU PIZZE'!$E$4:$E$110,B10,'MENU PIZZE'!$A$4:$A$110)+SUMIF('MENU PIZZE'!$F$4:$F$110,B10,'MENU PIZZE'!$A$4:$A$110)+SUMIF('MENU PIZZE'!$G$4:$G$110,B10,'MENU PIZZE'!$A$4:$A$110)+SUMIF('MENU PIZZE'!$H$4:$H$110,B10,'MENU PIZZE'!$A$4:$A$110)+SUMIF('MENU PIZZE'!$I$4:$I$110,B10,'MENU PIZZE'!$A$4:$A$110)+SUMIF('MENU PIZZE'!$J$4:$J$110,B10,'MENU PIZZE'!$A$4:$A$110)+SUMIF('MENU PIZZE'!$K$4:$K$110,B10,'MENU PIZZE'!$A$4:$A$110)+SUMIF('MENU PIZZE'!$L$4:$L$110,B10,'MENU PIZZE'!$A$4:$A$110) -> 2 | E10: =if(AND(D10>0,D10=C10), "SI","") | F10: =IF(G10>0,"SI","") -> SI | G10: =Max(C10-D10,0) -> 2 | H10: =countif('MENU PIZZE'!$E$4:$L$110,B10) -> 12 | I10: =IFERROR(VLOOKUP(B10,'Ricette dei preparati'!B:D,3,FALSE),"")
A11: 4.Verdure | B11: Funghi | C11: =SUMIF('MENU PIZZE'!$E$4:$E$110,B11,'MENU PIZZE'!$A$4:$A$110)+SUMIF('MENU PIZZE'!$F$4:$F$110,B11,'MENU PIZZE'!$A$4:$A$110)+SUMIF('MENU PIZZE'!$G$4:$G$110,B11,'MENU PIZZE'!$A$4:$A$110)+SUMIF('MENU PIZZE'!$H$4:$H$110,B11,'MENU PIZZE'!$A$4:$A$110)+SUMIF('MENU PIZZE'!$I$4:$I$110,B11,'MENU PIZZE'!$A$4:$A$110)+SUMIF('MENU PIZZE'!$J$4:$J$110,B11,'MENU PIZZE'!$A$4:$A$110)+SUMIF('MENU PIZZE'!$K$4:$K$110,B11,'MENU PIZZE'!$A$4:$A$110)+SUMIF('MENU PIZZE'!$L$4:$L$110,B11,'MENU PIZZE'!$A$4:$A$110) -> 1 | E11: =if(AND(D11>0,D11=C11), "SI","") | F11: =IF(G11>0,"SI","") -> SI | G11: =Max(C11-D11,0) -> 1 | H11: =countif('MENU PIZZE'!$E$4:$L$110,B11) -> 13 | I11: =IFERROR(VLOOKUP(B11,'Ricette dei preparati'!B:D,3,FALSE),"")
A12: 7.Spezie/Condim. | B12: Liquirizia polvere * | C12: =SUMIF('MENU PIZZE'!$E$4:$E$110,B12,'MENU PIZZE'!$A$4:$A$110)+SUMIF('MENU PIZZE'!$F$4:$F$110,B12,'MENU PIZZE'!$A$4:$A$110)+SUMIF('MENU PIZZE'!$G$4:$G$110,B12,'MENU PIZZE'!$A$4:$A$110)+SUMIF('MENU PIZZE'!$H$4:$H$110,B12,'MENU PIZZE'!$A$4:$A$110)+SUMIF('MENU PIZZE'!$I$4:$I$110,B12,'MENU PIZZE'!$A$4:$A$110)+SUMIF('MENU PIZZE'!$J$4:$J$110,B12,'MENU PIZZE'!$A$4:$A$110)+SUMIF('MENU PIZZE'!$K$4:$K$110,B12,'MENU PIZZE'!$A$4:$A$110)+SUMIF('MENU PIZZE'!$L$4:$L$110,B12,'MENU PIZZE'!$A$4:$A$110) -> 1 | E12: =if(AND(D12>0,D12=C12), "SI","") | F12: =IF(G12>0,"SI","") -> SI | G12: =Max(C12-D12,0) -> 1 | H12: =countif('MENU PIZZE'!$E$4:$L$110,B12) -> 1 | I12: =IFERROR(VLOOKUP(B12,'Ricette dei preparati'!B:D,3,FALSE),"")
A13: 7.Spezie/Condim. | B13: Pepe * | C13: =SUMIF('MENU PIZZE'!$E$4:$E$110,B13,'MENU PIZZE'!$A$4:$A$110)+SUMIF('MENU PIZZE'!$F$4:$F$110,B13,'MENU PIZZE'!$A$4:$A$110)+SUMIF('MENU PIZZE'!$G$4:$G$110,B13,'MENU PIZZE'!$A$4:$A$110)+SUMIF('MENU PIZZE'!$H$4:$H$110,B13,'MENU PIZZE'!$A$4:$A$110)+SUMIF('MENU PIZZE'!$I$4:$I$110,B13,'MENU PIZZE'!$A$4:$A$110)+SUMIF('MENU PIZZE'!$J$4:$J$110,B13,'MENU PIZZE'!$A$4:$A$110)+SUMIF('MENU PIZZE'!$K$4:$K$110,B13,'MENU PIZZE'!$A$4:$A$110)+SUMIF('MENU PIZZE'!$L$4:$L$110,B13,'MENU PIZZE'!$A$4:$A$110) -> 1 | E13: =if(AND(D13>0,D13=C13), "SI","") | F13: =IF(G13>0,"SI","") -> SI | G13: =Max(C13-D13,0) -> 1 | H13: =countif('MENU PIZZE'!$E$4:$L$110,B13) -> 20 | I13: =IFERROR(VLOOKUP(B13,'Ricette dei preparati'!B:D,3,FALSE),"")
A14: 7.Spezie/Condim. | B14: Prezzemolo | C14: =SUMIF('MENU PIZZE'!$E$4:$E$110,B14,'MENU PIZZE'!$A$4:$A$110)+SUMIF('MENU PIZZE'!$F$4:$F$110,B14,'MENU PIZZE'!$A$4:$A$110)+SUMIF('MENU PIZZE'!$G$4:$G$110,B14,'MENU PIZZE'!$A$4:$A$110)+SUMIF('MENU PIZZE'!$H$4:$H$110,B14,'MENU PIZZE'!$A$4:$A$110)+SUMIF('MENU PIZZE'!$I$4:$I$110,B14,'MENU PIZZE'!$A$4:$A$110)+SUMIF('MENU PIZZE'!$J$4:$J$110,B14,'MENU PIZZE'!$A$4:$A$110)+SUMIF('MENU PIZZE'!$K$4:$K$110,B14,'MENU PIZZE'!$A$4:$A$110)+SUMIF('MENU PIZZE'!$L$4:$L$110,B14,'MENU PIZZE'!$A$4:$A$110) -> 1 | E14: =if(AND(D14>0,D14=C14), "SI","") | F14: =IF(G14>0,"SI","") -> SI | G14: =Max(C14-D14,0) -> 1 | H14: =countif('MENU PIZZE'!$E$4:$L$110,B14) -> 2 | I14: =IFERROR(VLOOKUP(B14,'Ricette dei preparati'!B:D,3,FALSE),"")
... A24: 1.Formaggi | B24: Caprino | C24: =SUMIF('MENU PIZZE'!$E$4:$E$110,B24,'MENU PIZZE'!$A$4:$A$110)+SUMIF('MENU PIZZE'!$F$4:$F$110,B24,'MENU PIZZE'!$A$4:$A$110)+SUMIF('MENU PIZZE'!$G$4:$G$110,B24,'MENU PIZZE'!$A$4:$A$110)+SUMIF('MENU PIZZE'!$H$4:$H$110,B24,'MENU PIZZE'!$A$4:$A$110)+SUMIF('MENU PIZZE'!$I$4:$I$110,B24,'MENU PIZZE'!$A$4:$A$110)+SUMIF('MENU PIZZE'!$J$4:$J$110,B24,'MENU PIZZE'!$A$4:$A$110)+SUMIF('MENU PIZZE'!$K$4:$K$110,B24,'MENU PIZZE'!$A$4:$A$110)+SUMIF('MENU PIZZE'!$L$4:$L$110,B24,'MENU PIZZE'!$A$4:$A$110) -> 0 | E24: =if(AND(D24>0,D24=C24), "SI","") | F24: =IF(G24>0,"SI","") | G24: =Max(C24-D24,0) -> 0 | H24: =countif('MENU PIZZE'!$E$4:$L$110,B24) -> 2 | I24: =IFERROR(VLOOKUP(B24,'Ricette dei preparati'!B:D,3,FALSE),"")
A25: 1.Formaggi | B25: Cheddar | C25: =SUMIF('MENU PIZZE'!$E$4:$E$110,B25,'MENU PIZZE'!$A$4:$A$110)+SUMIF('MENU PIZZE'!$F$4:$F$110,B25,'MENU PIZZE'!$A$4:$A$110)+SUMIF('MENU PIZZE'!$G$4:$G$110,B25,'MENU PIZZE'!$A$4:$A$110)+SUMIF('MENU PIZZE'!$H$4:$H$110,B25,'MENU PIZZE'!$A$4:$A$110)+SUMIF('MENU PIZZE'!$I$4:$I$110,B25,'MENU PIZZE'!$A$4:$A$110)+SUMIF('MENU PIZZE'!$J$4:$J$110,B25,'MENU PIZZE'!$A$4:$A$110)+SUMIF('MENU PIZZE'!$K$4:$K$110,B25,'MENU PIZZE'!$A$4:$A$110)+SUMIF('MENU PIZZE'!$L$4:$L$110,B25,'MENU PIZZE'!$A$4:$A$110) -> 0 | E25: =if(AND(D25>0,D25=C25), "SI","") | F25: =IF(G25>0,"SI","") | G25: =Max(C25-D25,0) -> 0 | H25: =COUNTIF('MENU PIZZE'!$E$4:$L$110,B25) -> 2 | I25: =IFERROR(VLOOKUP(B25,'Ricette dei preparati'!B:D,3,FALSE),"")
A26: 1.Formaggi | B26: Feta * | C26: =SUMIF('MENU PIZZE'!$E$4:$E$110,B26,'MENU PIZZE'!$A$4:$A$110)+SUMIF('MENU PIZZE'!$F$4:$F$110,B26,'MENU PIZZE'!$A$4:$A$110)+SUMIF('MENU PIZZE'!$G$4:$G$110,B26,'MENU PIZZE'!$A$4:$A$110)+SUMIF('MENU PIZZE'!$H$4:$H$110,B26,'MENU PIZZE'!$A$4:$A$110)+SUMIF('MENU PIZZE'!$I$4:$I$110,B26,'MENU PIZZE'!$A$4:$A$110)+SUMIF('MENU PIZZE'!$J$4:$J$110,B26,'MENU PIZZE'!$A$4:$A$110)+SUMIF('MENU PIZZE'!$K$4:$K$110,B26,'MENU PIZZE'!$A$4:$A$110)+SUMIF('MENU PIZZE'!$L$4:$L$110,B26,'MENU PIZZE'!$A$4:$A$110) -> 0 | E26: =if(AND(D26>0,D26=C26), "SI","") | F26: =IF(G26>0,"SI","") | G26: =Max(C26-D26,0) -> 0 | H26: =countif('MENU PIZZE'!$E$4:$L$110,B26) -> 2 | I26: =IFERROR(VLOOKUP(B26,'Ricette dei preparati'!B:D,3,FALSE),"")
A27: 1.Formaggi | B27: Fontina da fonduta | C27: =SUMIF('MENU PIZZE'!$E$4:$E$110,B27,'MENU PIZZE'!$A$4:$A$110)+SUMIF('MENU PIZZE'!$F$4:$F$110,B27,'MENU PIZZE'!$A$4:$A$110)+SUMIF('MENU PIZZE'!$G$4:$G$110,B27,'MENU PIZZE'!$A$4:$A$110)+SUMIF('MENU PIZZE'!$H$4:$H$110,B27,'MENU PIZZE'!$A$4:$A$110)+SUMIF('MENU PIZZE'!$I$4:$I$110,B27,'MENU PIZZE'!$A$4:$A$110)+SUMIF('MENU PIZZE'!$J$4:$J$110,B27,'MENU PIZZE'!$A$4:$A$110)+SUMIF('MENU PIZZE'!$K$4:$K$110,B27,'MENU PIZZE'!$A$4:$A$110)+SUMIF('MENU PIZZE'!$L$4:$L$110,B27,'MENU PIZZE'!$A$4:$A$110) -> 0 | E27: =if(AND(D27>0,D27=C27), "SI","") | F27: =IF(G27>0,"SI","") | G27: =Max(C27-D27,0) -> 0 | H27: =countif('MENU PIZZE'!$E$4:$L$110,B27) -> 1 | I27: =IFERROR(VLOOKUP(B27,'Ricette dei preparati'!B:D,3,FALSE),"")
A28: 1.Formaggi | B28: Pecorino romano | C28: =SUMIF('MENU PIZZE'!$E$4:$E$110,B28,'MENU PIZZE'!$A$4:$A$110)+SUMIF('MENU PIZZE'!$F$4:$F$110,B28,'MENU PIZZE'!$A$4:$A$110)+SUMIF('MENU PIZZE'!$G$4:$G$110,B28,'MENU PIZZE'!$A$4:$A$110)+SUMIF('MENU PIZZE'!$H$4:$H$110,B28,'MENU PIZZE'!$A$4:$A$110)+SUMIF('MENU PIZZE'!$I$4:$I$110,B28,'MENU PIZZE'!$A$4:$A$110)+SUMIF('MENU PIZZE'!$J$4:$J$110,B28,'MENU PIZZE'!$A$4:$A$110)+SUMIF('MENU PIZZE'!$K$4:$K$110,B28,'MENU PIZZE'!$A$4:$A$110)+SUMIF('MENU PIZZE'!$L$4:$L$110,B28,'MENU PIZZE'!$A$4:$A$110) -> 0 | E28: =if(AND(D28>0,D28=C28), "SI","") | F28: =IF(G28>0,"SI","") | G28: =Max(C28-D28,0) -> 0 | H28: =countif('MENU PIZZE'!$E$4:$L$110,B28) -> 3 | I28: =IFERROR(VLOOKUP(B28,'Ricette dei preparati'!B:D,3,FALSE),"")
A29: 1.Formaggi | B29: Provola affumicata | C29: =SUMIF('MENU PIZZE'!$E$4:$E$110,B29,'MENU PIZZE'!$A$4:$A$110)+SUMIF('MENU PIZZE'!$F$4:$F$110,B29,'MENU PIZZE'!$A$4:$A$110)+SUMIF('MENU PIZZE'!$G$4:$G$110,B29,'MENU PIZZE'!$A$4:$A$110)+SUMIF('MENU PIZZE'!$H$4:$H$110,B29,'MENU PIZZE'!$A$4:$A$110)+SUMIF('MENU PIZZE'!$I$4:$I$110,B29,'MENU PIZZE'!$A$4:$A$110)+SUMIF('MENU PIZZE'!$J$4:$J$110,B29,'MENU PIZZE'!$A$4:$A$110)+SUMIF('MENU PIZZE'!$K$4:$K$110,B29,'MENU PIZZE'!$A$4:$A$110)+SUMIF('MENU PIZZE'!$L$4:$L$110,B29,'MENU PIZZE'!$A$4:$A$110) -> 0 | E29: =if(AND(D29>0,D29=C29), "SI","") | F29: =IF(G29>0,"SI","") | G29: =Max(C29-D29,0) -> 0 | H29: =countif('MENU PIZZE'!$E$4:$L$110,B29) -> 16 | I29: =IFERROR(VLOOKUP(B29,'Ricette dei preparati'!B:D,3,FALSE),"")
A30: 1.Formaggi | B30: Ricotta * | C30: =SUMIF('MENU PIZZE'!$E$4:$E$110,B30,'MENU PIZZE'!$A$4:$A$110)+SUMIF('MENU PIZZE'!$F$4:$F$110,B30,'MENU PIZZE'!$A$4:$A$110)+SUMIF('MENU PIZZE'!$G$4:$G$110,B30,'MENU PIZZE'!$A$4:$A$110)+SUMIF('MENU PIZZE'!$H$4:$H$110,B30,'MENU PIZZE'!$A$4:$A$110)+SUMIF('MENU PIZZE'!$I$4:$I$110,B30,'MENU PIZZE'!$A$4:$A$110)+SUMIF('MENU PIZZE'!$J$4:$J$110,B30,'MENU PIZZE'!$A$4:$A$110)+SUMIF('MENU PIZZE'!$K$4:$K$110,B30,'MENU PIZZE'!$A$4:$A$110)+SUMIF('MENU PIZZE'!$L$4:$L$110,B30,'MENU PIZZE'!$A$4:$A$110) -> 0 | E30: =if(AND(D30>0,D30=C30), "SI","") | F30: =IF(G30>0,"SI","") | G30: =Max(C30-D30,0) -> 0 | H30: =countif('MENU PIZZE'!$E$4:$L$110,B30) -> 2 | I30: =IFERROR(VLOOKUP(B30,'Ricette dei preparati'!B:D,3,FALSE),"")
A31: 1.Formaggi | B31: Taleggio | C31: =SUMIF('MENU PIZZE'!$E$4:$E$110,B31,'MENU PIZZE'!$A$4:$A$110)+SUMIF('MENU PIZZE'!$F$4:$F$110,B31,'MENU PIZZE'!$A$4:$A$110)+SUMIF('MENU PIZZE'!$G$4:$G$110,B31,'MENU PIZZE'!$A$4:$A$110)+SUMIF('MENU PIZZE'!$H$4:$H$110,B31,'MENU PIZZE'!$A$4:$A$110)+SUMIF('MENU PIZZE'!$I$4:$I$110,B31,'MENU PIZZE'!$A$4:$A$110)+SUMIF('MENU PIZZE'!$J$4:$J$110,B31,'MENU PIZZE'!$A$4:$A$110)+SUMIF('MENU PIZZE'!$K$4:$K$110,B31,'MENU PIZZE'!$A$4:$A$110)+SUMIF('MENU PIZZE'!$L$4:$L$110,B31,'MENU PIZZE'!$A$4:$A$110) -> 0 | E31: =if(AND(D31>0,D31=C31), "SI","") | F31: =IF(G31>0,"SI","") | G31: =Max(C31-D31,0) -> 0 | H31: =countif('MENU PIZZE'!$E$4:$L$110,B31) -> 3 | I31: =IFERROR(VLOOKUP(B31,'Ricette dei preparati'!B:D,3,FALSE),"")
A32: 2.Salumi | B32: Bacon | C32: =SUMIF('MENU PIZZE'!$E$4:$E$110,B32,'MENU PIZZE'!$A$4:$A$110)+SUMIF('MENU PIZZE'!$F$4:$F$110,B32,'MENU PIZZE'!$A$4:$A$110)+SUMIF('MENU PIZZE'!$G$4:$G$110,B32,'MENU PIZZE'!$A$4:$A$110)+SUMIF('MENU PIZZE'!$H$4:$H$110,B32,'MENU PIZZE'!$A$4:$A$110)+SUMIF('MENU PIZZE'!$I$4:$I$110,B32,'MENU PIZZE'!$A$4:$A$110)+SUMIF('MENU PIZZE'!$J$4:$J$110,B32,'MENU PIZZE'!$A$4:$A$110)+SUMIF('MENU PIZZE'!$K$4:$K$110,B32,'MENU PIZZE'!$A$4:$A$110)+SUMIF('MENU PIZZE'!$L$4:$L$110,B32,'MENU PIZZE'!$A$4:$A$110) -> 0 | E32: =if(AND(D32>0,D32=C32), "SI","") | F32: =IF(G32>0,"SI","") | G32: =Max(C32-D32,0) -> 0 | H32: =countif('MENU PIZZE'!$E$4:$L$110,B32) -> 3 | I32: =IFERROR(VLOOKUP(B32,'Ricette dei preparati'!B:D,3,FALSE),"")
A33: 2.Salumi | B33: Bresaola | C33: =SUMIF('MENU PIZZE'!$E$4:$E$110,B33,'MENU PIZZE'!$A$4:$A$110)+SUMIF('MENU PIZZE'!$F$4:$F$110,B33,'MENU PIZZE'!$A$4:$A$110)+SUMIF('MENU PIZZE'!$G$4:$G$110,B33,'MENU PIZZE'!$A$4:$A$110)+SUMIF('MENU PIZZE'!$H$4:$H$110,B33,'MENU PIZZE'!$A$4:$A$110)+SUMIF('MENU PIZZE'!$I$4:$I$110,B33,'MENU PIZZE'!$A$4:$A$110)+SUMIF('MENU PIZZE'!$J$4:$J$110,B33,'MENU PIZZE'!$A$4:$A$110)+SUMIF('MENU PIZZE'!$K$4:$K$110,B33,'MENU PIZZE'!$A$4:$A$110)+SUMIF('MENU PIZZE'!$L$4:$L$110,B33,'MENU PIZZE'!$A$4:$A$110) -> 0 | E33: =if(AND(D33>0,D33=C33), "SI","") | F33: =IF(G33>0,"SI","") | G33: =Max(C33-D33,0) -> 0 | H33: =countif('MENU PIZZE'!$E$4:$L$110,B33) -> 2 | I33: =IFERROR(VLOOKUP(B33,'Ricette dei preparati'!B:D,3,FALSE),"")
A34: 2.Salumi | B34: Capocollo | C34: =SUMIF('MENU PIZZE'!$E$4:$E$110,B34,'MENU PIZZE'!$A$4:$A$110)+SUMIF('MENU PIZZE'!$F$4:$F$110,B34,'MENU PIZZE'!$A$4:$A$110)+SUMIF('MENU PIZZE'!$G$4:$G$110,B34,'MENU PIZZE'!$A$4:$A$110)+SUMIF('MENU PIZZE'!$H$4:$H$110,B34,'MENU PIZZE'!$A$4:$A$110)+SUMIF('MENU PIZZE'!$I$4:$I$110,B34,'MENU PIZZE'!$A$4:$A$110)+SUMIF('MENU PIZZE'!$J$4:$J$110,B34,'MENU PIZZE'!$A$4:$A$110)+SUMIF('MENU PIZZE'!$K$4:$K$110,B34,'MENU PIZZE'!$A$4:$A$110)+SUMIF('MENU PIZZE'!$L$4:$L$110,B34,'MENU PIZZE'!$A$4:$A$110) -> 0 | E34: =if(AND(D34>0,D34=C34), "SI","") | F34: =IF(G34>0,"SI","") | G34: =Max(C34-D34,0) -> 0 | H34: =countif('MENU PIZZE'!$E$4:$L$110,B34) -> 2 | I34: =IFERROR(VLOOKUP(B34,'Ricette dei preparati'!B:D,3,FALSE),"")
A35: 2.Salumi | B35: Cotto | C35: =SUMIF('MENU PIZZE'!$E$4:$E$110,B35,'MENU PIZZE'!$A$4:$A$110)+SUMIF('MENU PIZZE'!$F$4:$F$110,B35,'MENU PIZZE'!$A$4:$A$110)+SUMIF('MENU PIZZE'!$G$4:$G$110,B35,'MENU PIZZE'!$A$4:$A$110)+SUMIF('MENU PIZZE'!$H$4:$H$110,B35,'MENU PIZZE'!$A$4:$A$110)+SUMIF('MENU PIZZE'!$I$4:$I$110,B35,'MENU PIZZE'!$A$4:$A$110)+SUMIF('MENU PIZZE'!$J$4:$J$110,B35,'MENU PIZZE'!$A$4:$A$110)+SUMIF('MENU PIZZE'!$K$4:$K$110,B35,'MENU PIZZE'!$A$4:$A$110)+SUMIF('MENU PIZZE'!$L$4:$L$110,B35,'MENU PIZZE'!$A$4:$A$110) -> 0 | E35: =if(AND(D35>0,D35=C35), "SI","") | F35: =IF(G35>0,"SI","") | G35: =Max(C35-D35,0) -> 0 | H35: =countif('MENU PIZZE'!$E$4:$L$110,B35) -> 4 | I35: =IFERROR(VLOOKUP(B35,'Ricette dei preparati'!B:D,3,FALSE),"")
A36: 2.Salumi | B36: Crudo * | C36: =SUMIF('MENU PIZZE'!$E$4:$E$110,B36,'MENU PIZZE'!$A$4:$A$110)+SUMIF('MENU PIZZE'!$F$4:$F$110,B36,'MENU PIZZE'!$A$4:$A$110)+SUMIF('MENU PIZZE'!$G$4:$G$110,B36,'MENU PIZZE'!$A$4:$A$110)+SUMIF('MENU PIZZE'!$H$4:$H$110,B36,'MENU PIZZE'!$A$4:$A$110)+SUMIF('MENU PIZZE'!$I$4:$I$110,B36,'MENU PIZZE'!$A$4:$A$110)+SUMIF('MENU PIZZE'!$J$4:$J$110,B36,'MENU PIZZE'!$A$4:$A$110)+SUMIF('MENU PIZZE'!$K$4:$K$110,B36,'MENU PIZZE'!$A$4:$A$110)+SUMIF('MENU PIZZE'!$L$4:$L$110,B36,'MENU PIZZE'!$A$4:$A$110) -> 0 | E36: =if(AND(D36>0,D36=C36), "SI","") | F36: =IF(G36>0,"SI","") | G36: =Max(C36-D36,0) -> 0 | H36: =COUNTIF('MENU PIZZE'!$E$4:$L$110,B36) -> 7 | I36: =IFERROR(VLOOKUP(B36,'Ricette dei preparati'!B:D,3,FALSE),"")
A37: 2.Salumi | B37: Finocchiona | C37: =SUMIF('MENU PIZZE'!$E$4:$E$110,B37,'MENU PIZZE'!$A$4:$A$110)+SUMIF('MENU PIZZE'!$F$4:$F$110,B37,'MENU PIZZE'!$A$4:$A$110)+SUMIF('MENU PIZZE'!$G$4:$G$110,B37,'MENU PIZZE'!$A$4:$A$110)+SUMIF('MENU PIZZE'!$H$4:$H$110,B37,'MENU PIZZE'!$A$4:$A$110)+SUMIF('MENU PIZZE'!$I$4:$I$110,B37,'MENU PIZZE'!$A$4:$A$110)+SUMIF('MENU PIZZE'!$J$4:$J$110,B37,'MENU PIZZE'!$A$4:$A$110)+SUMIF('MENU PIZZE'!$K$4:$K$110,B37,'MENU PIZZE'!$A$4:$A$110)+SUMIF('MENU PIZZE'!$L$4:$L$110,B37,'MENU PIZZE'!$A$4:$A$110) -> 0 | E37: =if(AND(D37>0,D37=C37), "SI","") | F37: =IF(G37>0,"SI","") | G37: =Max(C37-D37,0) -> 0 | H37: =countif('MENU PIZZE'!$E$4:$L$110,B37) -> 1 | I37: =IFERROR(VLOOKUP(B37,'Ricette dei preparati'!B:D,3,FALSE),"")
A38: 2.Salumi | B38: Lardo * | C38: =SUMIF('MENU PIZZE'!$E$4:$E$110,B38,'MENU PIZZE'!$A$4:$A$110)+SUMIF('MENU PIZZE'!$F$4:$F$110,B38,'MENU PIZZE'!$A$4:$A$110)+SUMIF('MENU PIZZE'!$G$4:$G$110,B38,'MENU PIZZE'!$A$4:$A$110)+SUMIF('MENU PIZZE'!$H$4:$H$110,B38,'MENU PIZZE'!$A$4:$A$110)+SUMIF('MENU PIZZE'!$I$4:$I$110,B38,'MENU PIZZE'!$A$4:$A$110)+SUMIF('MENU PIZZE'!$J$4:$J$110,B38,'MENU PIZZE'!$A$4:$A$110)+SUMIF('MENU PIZZE'!$K$4:$K$110,B38,'MENU PIZZE'!$A$4:$A$110)+SUMIF('MENU PIZZE'!$L$4:$L$110,B38,'MENU PIZZE'!$A$4:$A$110) -> 0 | E38: =if(AND(D38>0,D38=C38), "SI","") | F38: =IF(G38>0,"SI","") | G38: =Max(C38-D38,0) -> 0 | H38: =countif('MENU PIZZE'!$E$4:$L$110,B38) -> 2 | I38: =IFERROR(VLOOKUP(B38,'Ricette dei preparati'!B:D,3,FALSE),"")
A39: 2.Salumi | B39: Mortadella | C39: =SUMIF('MENU PIZZE'!$E$4:$E$110,B39,'MENU PIZZE'!$A$4:$A$110)+SUMIF('MENU PIZZE'!$F$4:$F$110,B39,'MENU PIZZE'!$A$4:$A$110)+SUMIF('MENU PIZZE'!$G$4:$G$110,B39,'MENU PIZZE'!$A$4:$A$110)+SUMIF('MENU PIZZE'!$H$4:$H$110,B39,'MENU PIZZE'!$A$4:$A$110)+SUMIF('MENU PIZZE'!$I$4:$I$110,B39,'MENU PIZZE'!$A$4:$A$110)+SUMIF('MENU PIZZE'!$J$4:$J$110,B39,'MENU PIZZE'!$A$4:$A$110)+SUMIF('MENU PIZZE'!$K$4:$K$110,B39,'MENU PIZZE'!$A$4:$A$110)+SUMIF('MENU PIZZE'!$L$4:$L$110,B39,'MENU PIZZE'!$A$4:$A$110) -> 0 | E39: =if(AND(D39>0,D39=C39), "SI","") | F39: =IF(G39>0,"SI","") | G39: =Max(C39-D39,0) -> 0 | H39: =countif('MENU PIZZE'!$E$4:$L$110,B39) -> 2 | I39: =IFERROR(VLOOKUP(B39,'Ricette dei preparati'!B:D,3,FALSE),"")
A40: 2.Salumi | B40: Nduja | C40: =SUMIF('MENU PIZZE'!$E$4:$E$110,B40,'MENU PIZZE'!$A$4:$A$110)+SUMIF('MENU PIZZE'!$F$4:$F$110,B40,'MENU PIZZE'!$A$4:$A$110)+SUMIF('MENU PIZZE'!$G$4:$G$110,B40,'MENU PIZZE'!$A$4:$A$110)+SUMIF('MENU PIZZE'!$H$4:$H$110,B40,'MENU PIZZE'!$A$4:$A$110)+SUMIF('MENU PIZZE'!$I$4:$I$110,B40,'MENU PIZZE'!$A$4:$A$110)+SUMIF('MENU PIZZE'!$J$4:$J$110,B40,'MENU PIZZE'!$A$4:$A$110)+SUMIF('MENU PIZZE'!$K$4:$K$110,B40,'MENU PIZZE'!$A$4:$A$110)+SUMIF('MENU PIZZE'!$L$4:$L$110,B40,'MENU PIZZE'!$A$4:$A$110) -> 0 | E40: =if(AND(D40>0,D40=C40), "SI","") | F40: =IF(G40>0,"SI","") | G40: =Max(C40-D40,0) -> 0 | H40: =countif('MENU PIZZE'!$E$4:$L$110,B40) -> 1 | I40: =IFERROR(VLOOKUP(B40,'Ricette dei preparati'!B:D,3,FALSE),"")
A41: 2.Salumi | B41: Pancetta * | C41: =SUMIF('MENU PIZZE'!$E$4:$E$110,B41,'MENU PIZZE'!$A$4:$A$110)+SUMIF('MENU PIZZE'!$F$4:$F$110,B41,'MENU PIZZE'!$A$4:$A$110)+SUMIF('MENU PIZZE'!$G$4:$G$110,B41,'MENU PIZZE'!$A$4:$A$110)+SUMIF('MENU PIZZE'!$H$4:$H$110,B41,'MENU PIZZE'!$A$4:$A$110)+SUMIF('MENU PIZZE'!$I$4:$I$110,B41,'MENU PIZZE'!$A$4:$A$110)+SUMIF('MENU PIZZE'!$J$4:$J$110,B41,'MENU PIZZE'!$A$4:$A$110)+SUMIF('MENU PIZZE'!$K$4:$K$110,B41,'MENU PIZZE'!$A$4:$A$110)+SUMIF('MENU PIZZE'!$L$4:$L$110,B41,'MENU PIZZE'!$A$4:$A$110) -> 0 | E41: =if(AND(D41>0,D41=C41), "SI","") | F41: =IF(G41>0,"SI","") | G41: =Max(C41-D41,0) -> 0 | H41: =COUNTIF('MENU PIZZE'!$E$4:$L$110,B41) -> 2 | I41: =IFERROR(VLOOKUP(B41,'Ricette dei preparati'!B:D,3,FALSE),"")
A42: 2.Salumi | B42: Porchetta | C42: =SUMIF('MENU PIZZE'!$E$4:$E$110,B42,'MENU PIZZE'!$A$4:$A$110)+SUMIF('MENU PIZZE'!$F$4:$F$110,B42,'MENU PIZZE'!$A$4:$A$110)+SUMIF('MENU PIZZE'!$G$4:$G$110,B42,'MENU PIZZE'!$A$4:$A$110)+SUMIF('MENU PIZZE'!$H$4:$H$110,B42,'MENU PIZZE'!$A$4:$A$110)+SUMIF('MENU PIZZE'!$I$4:$I$110,B42,'MENU PIZZE'!$A$4:$A$110)+SUMIF('MENU PIZZE'!$J$4:$J$110,B42,'MENU PIZZE'!$A$4:$A$110)+SUMIF('MENU PIZZE'!$K$4:$K$110,B42,'MENU PIZZE'!$A$4:$A$110)+SUMIF('MENU PIZZE'!$L$4:$L$110,B42,'MENU PIZZE'!$A$4:$A$110) -> 0 | E42: =if(AND(D42>0,D42=C42), "SI","") | F42: =IF(G42>0,"SI","") | G42: =Max(C42-D42,0) -> 0 | H42: =countif('MENU PIZZE'!$E$4:$L$110,B42) -> 2 | I42: =IFERROR(VLOOKUP(B42,'Ricette dei preparati'!B:D,3,FALSE),"")
A43: 2.Salumi | B43: Salame piccante | C43: =SUMIF('MENU PIZZE'!$E$4:$E$110,B43,'MENU PIZZE'!$A$4:$A$110)+SUMIF('MENU PIZZE'!$F$4:$F$110,B43,'MENU PIZZE'!$A$4:$A$110)+SUMIF('MENU PIZZE'!$G$4:$G$110,B43,'MENU PIZZE'!$A$4:$A$110)+SUMIF('MENU PIZZE'!$H$4:$H$110,B43,'MENU PIZZE'!$A$4:$A$110)+SUMIF('MENU PIZZE'!$I$4:$I$110,B43,'MENU PIZZE'!$A$4:$A$110)+SUMIF('MENU PIZZE'!$J$4:$J$110,B43,'MENU PIZZE'!$A$4:$A$110)+SUMIF('MENU PIZZE'!$K$4:$K$110,B43,'MENU PIZZE'!$A$4:$A$110)+SUMIF('MENU PIZZE'!$L$4:$L$110,B43,'MENU PIZZE'!$A$4:$A$110) -> 0 | E43: =if(AND(D43>0,D43=C43), "SI","") | F43: =IF(G43>0,"SI","") | G43: =Max(C43-D43,0) -> 0 | H43: =countif('MENU PIZZE'!$E$4:$L$110,B43) -> 3 | I43: =IFERROR(VLOOKUP(B43,'Ricette dei preparati'!B:D,3,FALSE),"")
A44: 2.Salumi | B44: Salsiccia | C44: =SUMIF('MENU PIZZE'!$E$4:$E$110,B44,'MENU PIZZE'!$A$4:$A$110)+SUMIF('MENU PIZZE'!$F$4:$F$110,B44,'MENU PIZZE'!$A$4:$A$110)+SUMIF('MENU PIZZE'!$G$4:$G$110,B44,'MENU PIZZE'!$A$4:$A$110)+SUMIF('MENU PIZZE'!$H$4:$H$110,B44,'MENU PIZZE'!$A$4:$A$110)+SUMIF('MENU PIZZE'!$I$4:$I$110,B44,'MENU PIZZE'!$A$4:$A$110)+SUMIF('MENU PIZZE'!$J$4:$J$110,B44,'MENU PIZZE'!$A$4:$A$110)+SUMIF('MENU PIZZE'!$K$4:$K$110,B44,'MENU PIZZE'!$A$4:$A$110)+SUMIF('MENU PIZZE'!$L$4:$L$110,B44,'MENU PIZZE'!$A$4:$A$110) -> 0 | E44: =if(AND(D44>0,D44=C44), "SI","") | F44: =IF(G44>0,"SI","") | G44: =Max(C44-D44,0) -> 0 | H44: =countif('MENU PIZZE'!$E$4:$L$110,B44) -> 4 | I44: =IFERROR(VLOOKUP(B44,'Ricette dei preparati'!B:D,3,FALSE),"")
A45: 2.Salumi | B45: Speck | C45: =SUMIF('MENU PIZZE'!$E$4:$E$110,B45,'MENU PIZZE'!$A$4:$A$110)+SUMIF('MENU PIZZE'!$F$4:$F$110,B45,'MENU PIZZE'!$A$4:$A$110)+SUMIF('MENU PIZZE'!$G$4:$G$110,B45,'MENU PIZZE'!$A$4:$A$110)+SUMIF('MENU PIZZE'!$H$4:$H$110,B45,'MENU PIZZE'!$A$4:$A$110)+SUMIF('MENU PIZZE'!$I$4:$I$110,B45,'MENU PIZZE'!$A$4:$A$110)+SUMIF('MENU PIZZE'!$J$4:$J$110,B45,'MENU PIZZE'!$A$4:$A$110)+SUMIF('MENU PIZZE'!$K$4:$K$110,B45,'MENU PIZZE'!$A$4:$A$110)+SUMIF('MENU PIZZE'!$L$4:$L$110,B45,'MENU PIZZE'!$A$4:$A$110) -> 0 | E45: =if(AND(D45>0,D45=C45), "SI","") | F45: =IF(G45>0,"SI","") | G45: =Max(C45-D45,0) -> 0 | H45: =countif('MENU PIZZE'!$E$4:$L$110,B45) -> 7 | I45: =IFERROR(VLOOKUP(B45,'Ricette dei preparati'!B:D,3,FALSE),"")
